Workbook

Sheet 1_Rh110 in H20
A1: Corr.Time [ms] | B1: Rh110 | C1: Parameters | E1: model f | F1: res | G1: chi2 | J1: Count rate [kHz] | L1: kcpm
A2: 4e-06 | B2: 1.14349 | C2: offset | D2: 1.0002765 | E2: =$D$2+1/$D$3*($D$8/(1+A2/$D$4)/SQRT(1+A2/$D$4/$D$5/$D$5)+(1-$D$8)/(1+A2/$D$6)/SQRT(1+A2/$D$6/$D$7/$D$7))*(1+$D$9*EXP(-A2/$D$10)+$D$11*EXP(-A2/$D$12)) -> 1.2439244 | F2: =B2-E2 -> -0.10043444 | G2: =SUMSQ(F$4:F$190) -> 0.0036369597 | I2: Ch.1 | J2: 102 | L2: =(J2+J3)/D3 -> 46.875217
A3: 8e-06 | B3: 1.22581 | C3: N | D3: 4.31358 | E3: =$D$2+1/$D$3*($D$8/(1+A3/$D$4)/SQRT(1+A3/$D$4/$D$5/$D$5)+(1-$D$8)/(1+A3/$D$6)/SQRT(1+A3/$D$6/$D$7/$D$7))*(1+$D$9*EXP(-A3/$D$10)+$D$11*EXP(-A3/$D$12)) -> 1.2439057 | F3: =B3-E3 -> -0.01809572 | I3: Ch.2 | J3: 100.2
A4: 1.2e-05 | B4: 1.237 | C4: tD1 [ms] | D4: 0.19143593 | E4: =$D$2+1/$D$3*($D$8/(1+A4/$D$4)/SQRT(1+A4/$D$4/$D$5/$D$5)+(1-$D$8)/(1+A4/$D$6)/SQRT(1+A4/$D$6/$D$7/$D$7))*(1+$D$9*EXP(-A4/$D$10)+$D$11*EXP(-A4/$D$12)) -> 1.243887 | F4: =B4-E4 -> -0.0068870143
A5: 1.6e-05 | B5: 1.24708 | C5: Zo/Wo | D5: 5.5544429 | E5: =$D$2+1/$D$3*($D$8/(1+A5/$D$4)/SQRT(1+A5/$D$4/$D$5/$D$5)+(1-$D$8)/(1+A5/$D$6)/SQRT(1+A5/$D$6/$D$7/$D$7))*(1+$D$9*EXP(-A5/$D$10)+$D$11*EXP(-A5/$D$12)) -> 1.2438683 | F5: =B5-E5 -> 0.0032116751
A6: 2e-05 | B6: 1.24504 | C6: tD2 [ms] | D6: 1.38 | E6: =$D$2+1/$D$3*($D$8/(1+A6/$D$4)/SQRT(1+A6/$D$4/$D$5/$D$5)+(1-$D$8)/(1+A6/$D$6)/SQRT(1+A6/$D$6/$D$7/$D$7))*(1+$D$9*EXP(-A6/$D$10)+$D$11*EXP(-A6/$D$12)) -> 1.2438497 | F6: =B6-E6 -> 0.0011903483
A7: 2.4e-05 | B7: 1.23202 | C7: Zo/Wo | D7: =D5 -> 5.5544429 | E7: =$D$2+1/$D$3*($D$8/(1+A7/$D$4)/SQRT(1+A7/$D$4/$D$5/$D$5)+(1-$D$8)/(1+A7/$D$6)/SQRT(1+A7/$D$6/$D$7/$D$7))*(1+$D$9*EXP(-A7/$D$10)+$D$11*EXP(-A7/$D$12)) -> 1.243831 | F7: =B7-E7 -> -0.011810995
A8: 2.8e-05 | B8: 1.25939 | C8: x1 | D8: 1 | E8: =$D$2+1/$D$3*($D$8/(1+A8/$D$4)/SQRT(1+A8/$D$4/$D$5/$D$5)+(1-$D$8)/(1+A8/$D$6)/SQRT(1+A8/$D$6/$D$7/$D$7))*(1+$D$9*EXP(-A8/$D$10)+$D$11*EXP(-A8/$D$12)) -> 1.2438124 | F8: =B8-E8 -> 0.015577646
A9: 3.2e-05 | B9: 1.24545 | C9: KT | D9: 0.051075613 | E9: =$D$2+1/$D$3*($D$8/(1+A9/$D$4)/SQRT(1+A9/$D$4/$D$5/$D$5)+(1-$D$8)/(1+A9/$D$6)/SQRT(1+A9/$D$6/$D$7/$D$7))*(1+$D$9*EXP(-A9/$D$10)+$D$11*EXP(-A9/$D$12)) -> 1.2437937 | F9: =B9-E9 -> 0.0016562702
A10: 3.6e-05 | B10: 1.24494 | C10: tT [ms] | D10: 0.0034895597 | E10: =$D$2+1/$D$3*($D$8/(1+A10/$D$4)/SQRT(1+A10/$D$4/$D$5/$D$5)+(1-$D$8)/(1+A10/$D$6)/SQRT(1+A10/$D$6/$D$7/$D$7))*(1+$D$9*EXP(-A10/$D$10)+$D$11*EXP(-A10/$D$12)) -> 1.2437751 | F10: =B10-E10 -> 0.0011648784
A11: 4e-05 | B11: 1.25817 | C11: KR | D11: 0 | E11: =$D$2+1/$D$3*($D$8/(1+A11/$D$4)/SQRT(1+A11/$D$4/$D$5/$D$5)+(1-$D$8)/(1+A11/$D$6)/SQRT(1+A11/$D$6/$D$7/$D$7))*(1+$D$9*EXP(-A11/$D$10)+$D$11*EXP(-A11/$D$12)) -> 1.2437565 | F11: =B11-E11 -> 0.01441347
A12: 4.4e-05 | B12: 1.26326 | C12: tR [ms] | D12: 2.0644404e-05 | E12: =$D$2+1/$D$3*($D$8/(1+A12/$D$4)/SQRT(1+A12/$D$4/$D$5/$D$5)+(1-$D$8)/(1+A12/$D$6)/SQRT(1+A12/$D$6/$D$7/$D$7))*(1+$D$9*EXP(-A12/$D$10)+$D$11*EXP(-A12/$D$12)) -> 1.243738 | F12: =B12-E12 -> 0.019522046
A13: 4.8e-05 | B13: 1.22785 | E13: =$D$2+1/$D$3*($D$8/(1+A13/$D$4)/SQRT(1+A13/$D$4/$D$5/$D$5)+(1-$D$8)/(1+A13/$D$6)/SQRT(1+A13/$D$6/$D$7/$D$7))*(1+$D$9*EXP(-A13/$D$10)+$D$11*EXP(-A13/$D$12)) -> 1.2437194 | F13: =B13-E13 -> -0.015869394
A14: 5.2e-05 | B14: 1.25461 | E14: =$D$2+1/$D$3*($D$8/(1+A14/$D$4)/SQRT(1+A14/$D$4/$D$5/$D$5)+(1-$D$8)/(1+A14/$D$6)/SQRT(1+A14/$D$6/$D$7/$D$7))*(1+$D$9*EXP(-A14/$D$10)+$D$11*EXP(-A14/$D$12)) -> 1.2437009 | F14: =B14-E14 -> 0.01090915
A15: 5.6e-05 | B15: 1.23293 | E15: =$D$2+1/$D$3*($D$8/(1+A15/$D$4)/SQRT(1+A15/$D$4/$D$5/$D$5)+(1-$D$8)/(1+A15/$D$6)/SQRT(1+A15/$D$6/$D$7/$D$7))*(1+$D$9*EXP(-A15/$D$10)+$D$11*EXP(-A15/$D$12)) -> 1.2436823 | F15: =B15-E15 -> -0.010752323
A16: 6e-05 | B16: 1.22968 | E16: =$D$2+1/$D$3*($D$8/(1+A16/$D$4)/SQRT(1+A16/$D$4/$D$5/$D$5)+(1-$D$8)/(1+A16/$D$6)/SQRT(1+A16/$D$6/$D$7/$D$7))*(1+$D$9*EXP(-A16/$D$10)+$D$11*EXP(-A16/$D$12)) -> 1.2436638 | F16: =B16-E16 -> -0.013983811
A17: 6.4e-05 | B17: 1.24957 | E17: =$D$2+1/$D$3*($D$8/(1+A17/$D$4)/SQRT(1+A17/$D$4/$D$5/$D$5)+(1-$D$8)/(1+A17/$D$6)/SQRT(1+A17/$D$6/$D$7/$D$7))*(1+$D$9*EXP(-A17/$D$10)+$D$11*EXP(-A17/$D$12)) -> 1.2436453 | F17: =B17-E17 -> 0.0059246839
A18: 7.2e-05 | B18: 1.23705 | E18: =$D$2+1/$D$3*($D$8/(1+A18/$D$4)/SQRT(1+A18/$D$4/$D$5/$D$5)+(1-$D$8)/(1+A18/$D$6)/SQRT(1+A18/$D$6/$D$7/$D$7))*(1+$D$9*EXP(-A18/$D$10)+$D$11*EXP(-A18/$D$12)) -> 1.2436084 | F18: =B18-E18 -> -0.0065583735
A19: 8e-05 | B19: 1.25522 | E19: =$D$2+1/$D$3*($D$8/(1+A19/$D$4)/SQRT(1+A19/$D$4/$D$5/$D$5)+(1-$D$8)/(1+A19/$D$6)/SQRT(1+A19/$D$6/$D$7/$D$7))*(1+$D$9*EXP(-A19/$D$10)+$D$11*EXP(-A19/$D$12)) -> 1.2435715 | F19: =B19-E19 -> 0.011648505
A20: 8.8e-05 | B20: 1.26702 | E20: =$D$2+1/$D$3*($D$8/(1+A20/$D$4)/SQRT(1+A20/$D$4/$D$5/$D$5)+(1-$D$8)/(1+A20/$D$6)/SQRT(1+A20/$D$6/$D$7/$D$7))*(1+$D$9*EXP(-A20/$D$10)+$D$11*EXP(-A20/$D$12)) -> 1.2435347 | F20: =B20-E20 -> 0.02348532
A21: 9.6e-05 | B21: 1.2456 | E21: =$D$2+1/$D$3*($D$8/(1+A21/$D$4)/SQRT(1+A21/$D$4/$D$5/$D$5)+(1-$D$8)/(1+A21/$D$6)/SQRT(1+A21/$D$6/$D$7/$D$7))*(1+$D$9*EXP(-A21/$D$10)+$D$11*EXP(-A21/$D$12)) -> 1.2434979 | F21: =B21-E21 -> 0.0021020704
A22: 0.000104 | B22: 1.22133 | E22: =$D$2+1/$D$3*($D$8/(1+A22/$D$4)/SQRT(1+A22/$D$4/$D$5/$D$5)+(1-$D$8)/(1+A22/$D$6)/SQRT(1+A22/$D$6/$D$7/$D$7))*(1+$D$9*EXP(-A22/$D$10)+$D$11*EXP(-A22/$D$12)) -> 1.2434612 | F22: =B22-E22 -> -0.022131242
A23: 0.000112 | B23: 1.22942 | E23: =$D$2+1/$D$3*($D$8/(1+A23/$D$4)/SQRT(1+A23/$D$4/$D$5/$D$5)+(1-$D$8)/(1+A23/$D$6)/SQRT(1+A23/$D$6/$D$7/$D$7))*(1+$D$9*EXP(-A23/$D$10)+$D$11*EXP(-A23/$D$12)) -> 1.2434246 | F23: =B23-E23 -> -0.014004619
A24: 0.00012 | B24: 1.24733 | E24: =$D$2+1/$D$3*($D$8/(1+A24/$D$4)/SQRT(1+A24/$D$4/$D$5/$D$5)+(1-$D$8)/(1+A24/$D$6)/SQRT(1+A24/$D$6/$D$7/$D$7))*(1+$D$9*EXP(-A24/$D$10)+$D$11*EXP(-A24/$D$12)) -> 1.2433881 | F24: =B24-E24 -> 0.0039419417
... A238: 13958.644 | B238: 0.992593 | E238: =$D$2+1/$D$3*($D$8/(1+A238/$D$4)/SQRT(1+A238/$D$4/$D$5/$D$5)+(1-$D$8)/(1+A238/$D$6)/SQRT(1+A238/$D$6/$D$7/$D$7))*(1+$D$9*EXP(-A238/$D$10)+$D$11*EXP(-A238/$D$12)) -> 1.0002766 | F238: =B238-E238 -> -0.0076835904
A239: 15032.386 | B239: 0.99211
A240: 16106.127 | B240: 0.992146
A241: 17179.869 | B241: 0.99178
A242: 19327.353 | B242: 0.991509
A243: 21474.836 | B243: 0.991052
A244: 23622.32 | B244: 0.991789
A245: 25769.804 | B245: 0.99216
A246: 27917.287 | B246: 0.993672

Sheet 2_Rh110 in H20
A1: Corr.Time [ms] | B1: Rh110 | C1: Parameters | E1: model f | F1: res | G1: chi2 | J1: Count rate [kHz] | L1: kcpm
A2: 4e-06 | B2: 1.15476 | C2: offset | D2: 1.0002463 | E2: =$D$2+1/$D$3*($D$8/(1+A2/$D$4)/SQRT(1+A2/$D$4/$D$5/$D$5)+(1-$D$8)/(1+A2/$D$6)/SQRT(1+A2/$D$6/$D$7/$D$7))*(1+$D$9*EXP(-A2/$D$10)+$D$11*EXP(-A2/$D$12)) -> 1.2405267 | F2: =B2-E2 -> -0.085766733 | G2: =SUMSQ(F$4:F$190) -> 0.002537092 | I2: Ch.1 | J2: 104 | L2: =(J2+J3)/D3 -> 47.422695
A3: 8e-06 | B3: 1.20521 | C3: N | D3: 4.3439117 | E3: =$D$2+1/$D$3*($D$8/(1+A3/$D$4)/SQRT(1+A3/$D$4/$D$5/$D$5)+(1-$D$8)/(1+A3/$D$6)/SQRT(1+A3/$D$6/$D$7/$D$7))*(1+$D$9*EXP(-A3/$D$10)+$D$11*EXP(-A3/$D$12)) -> 1.2405105 | F3: =B3-E3 -> -0.035300504 | I3: Ch.2 | J3: 102
A4: 1.2e-05 | B4: 1.22672 | C4: tD1 [ms] | D4: 0.1900519 | E4: =$D$2+1/$D$3*($D$8/(1+A4/$D$4)/SQRT(1+A4/$D$4/$D$5/$D$5)+(1-$D$8)/(1+A4/$D$6)/SQRT(1+A4/$D$6/$D$7/$D$7))*(1+$D$9*EXP(-A4/$D$10)+$D$11*EXP(-A4/$D$12)) -> 1.2404943 | F4: =B4-E4 -> -0.013774287
A5: 1.6e-05 | B5: 1.23399 | C5: Zo/Wo | D5: 5.214606 | E5: =$D$2+1/$D$3*($D$8/(1+A5/$D$4)/SQRT(1+A5/$D$4/$D$5/$D$5)+(1-$D$8)/(1+A5/$D$6)/SQRT(1+A5/$D$6/$D$7/$D$7))*(1+$D$9*EXP(-A5/$D$10)+$D$11*EXP(-A5/$D$12)) -> 1.2404781 | F5: =B5-E5 -> -0.0064880835
A6: 2e-05 | B6: 1.23891 | C6: tD2 [ms] | D6: 1.38 | E6: =$D$2+1/$D$3*($D$8/(1+A6/$D$4)/SQRT(1+A6/$D$4/$D$5/$D$5)+(1-$D$8)/(1+A6/$D$6)/SQRT(1+A6/$D$6/$D$7/$D$7))*(1+$D$9*EXP(-A6/$D$10)+$D$11*EXP(-A6/$D$12)) -> 1.2404619 | F6: =B6-E6 -> -0.0015518928
A7: 2.4e-05 | B7: 1.24292 | C7: Zo/Wo | D7: =D5 -> 5.214606 | E7: =$D$2+1/$D$3*($D$8/(1+A7/$D$4)/SQRT(1+A7/$D$4/$D$5/$D$5)+(1-$D$8)/(1+A7/$D$6)/SQRT(1+A7/$D$6/$D$7/$D$7))*(1+$D$9*EXP(-A7/$D$10)+$D$11*EXP(-A7/$D$12)) -> 1.2404457 | F7: =B7-E7 -> 0.0024742851
A8: 2.8e-05 | B8: 1.24614 | C8: x1 | D8: 1 | E8: =$D$2+1/$D$3*($D$8/(1+A8/$D$4)/SQRT(1+A8/$D$4/$D$5/$D$5)+(1-$D$8)/(1+A8/$D$6)/SQRT(1+A8/$D$6/$D$7/$D$7))*(1+$D$9*EXP(-A8/$D$10)+$D$11*EXP(-A8/$D$12)) -> 1.2404295 | F8: =B8-E8 -> 0.0057104502
A9: 3.2e-05 | B9: 1.23624 | C9: KT | D9: 0.043827351 | E9: =$D$2+1/$D$3*($D$8/(1+A9/$D$4)/SQRT(1+A9/$D$4/$D$5/$D$5)+(1-$D$8)/(1+A9/$D$6)/SQRT(1+A9/$D$6/$D$7/$D$7))*(1+$D$9*EXP(-A9/$D$10)+$D$11*EXP(-A9/$D$12)) -> 1.2404134 | F9: =B9-E9 -> -0.0041733975
A10: 3.6e-05 | B10: 1.26813 | C10: tT [ms] | D10: 0.003636413 | E10: =$D$2+1/$D$3*($D$8/(1+A10/$D$4)/SQRT(1+A10/$D$4/$D$5/$D$5)+(1-$D$8)/(1+A10/$D$6)/SQRT(1+A10/$D$6/$D$7/$D$7))*(1+$D$9*EXP(-A10/$D$10)+$D$11*EXP(-A10/$D$12)) -> 1.2403973 | F10: =B10-E10 -> 0.027732742
A11: 4e-05 | B11: 1.24479 | C11: KR | D11: 0 | E11: =$D$2+1/$D$3*($D$8/(1+A11/$D$4)/SQRT(1+A11/$D$4/$D$5/$D$5)+(1-$D$8)/(1+A11/$D$6)/SQRT(1+A11/$D$6/$D$7/$D$7))*(1+$D$9*EXP(-A11/$D$10)+$D$11*EXP(-A11/$D$12)) -> 1.2403811 | F11: =B11-E11 -> 0.0044088688
A12: 4.4e-05 | B12: 1.25007 | C12: tR [ms] | D12: 2.0644404e-05 | E12: =$D$2+1/$D$3*($D$8/(1+A12/$D$4)/SQRT(1+A12/$D$4/$D$5/$D$5)+(1-$D$8)/(1+A12/$D$6)/SQRT(1+A12/$D$6/$D$7/$D$7))*(1+$D$9*EXP(-A12/$D$10)+$D$11*EXP(-A12/$D$12)) -> 1.240365 | F12: =B12-E12 -> 0.0097049828
A13: 4.8e-05 | B13: 1.23203 | E13: =$D$2+1/$D$3*($D$8/(1+A13/$D$4)/SQRT(1+A13/$D$4/$D$5/$D$5)+(1-$D$8)/(1+A13/$D$6)/SQRT(1+A13/$D$6/$D$7/$D$7))*(1+$D$9*EXP(-A13/$D$10)+$D$11*EXP(-A13/$D$12)) -> 1.2403489 | F13: =B13-E13 -> -0.008318916
A14: 5.2e-05 | B14: 1.23802 | E14: =$D$2+1/$D$3*($D$8/(1+A14/$D$4)/SQRT(1+A14/$D$4/$D$5/$D$5)+(1-$D$8)/(1+A14/$D$6)/SQRT(1+A14/$D$6/$D$7/$D$7))*(1+$D$9*EXP(-A14/$D$10)+$D$11*EXP(-A14/$D$12)) -> 1.2403328 | F14: =B14-E14 -> -0.0023128275
A15: 5.6e-05 | B15: 1.22681 | E15: =$D$2+1/$D$3*($D$8/(1+A15/$D$4)/SQRT(1+A15/$D$4/$D$5/$D$5)+(1-$D$8)/(1+A15/$D$6)/SQRT(1+A15/$D$6/$D$7/$D$7))*(1+$D$9*EXP(-A15/$D$10)+$D$11*EXP(-A15/$D$12)) -> 1.2403168 | F15: =B15-E15 -> -0.013506752
A16: 6e-05 | B16: 1.24488 | E16: =$D$2+1/$D$3*($D$8/(1+A16/$D$4)/SQRT(1+A16/$D$4/$D$5/$D$5)+(1-$D$8)/(1+A16/$D$6)/SQRT(1+A16/$D$6/$D$7/$D$7))*(1+$D$9*EXP(-A16/$D$10)+$D$11*EXP(-A16/$D$12)) -> 1.2403007 | F16: =B16-E16 -> 0.0045793114
A17: 6.4e-05 | B17: 1.23762 | E17: =$D$2+1/$D$3*($D$8/(1+A17/$D$4)/SQRT(1+A17/$D$4/$D$5/$D$5)+(1-$D$8)/(1+A17/$D$6)/SQRT(1+A17/$D$6/$D$7/$D$7))*(1+$D$9*EXP(-A17/$D$10)+$D$11*EXP(-A17/$D$12)) -> 1.2402846 | F17: =B17-E17 -> -0.0026646382
A18: 7.2e-05 | B18: 1.22677 | E18: =$D$2+1/$D$3*($D$8/(1+A18/$D$4)/SQRT(1+A18/$D$4/$D$5/$D$5)+(1-$D$8)/(1+A18/$D$6)/SQRT(1+A18/$D$6/$D$7/$D$7))*(1+$D$9*EXP(-A18/$D$10)+$D$11*EXP(-A18/$D$12)) -> 1.2402526 | F18: =B18-E18 -> -0.013482575
A19: 8e-05 | B19: 1.24587 | E19: =$D$2+1/$D$3*($D$8/(1+A19/$D$4)/SQRT(1+A19/$D$4/$D$5/$D$5)+(1-$D$8)/(1+A19/$D$6)/SQRT(1+A19/$D$6/$D$7/$D$7))*(1+$D$9*EXP(-A19/$D$10)+$D$11*EXP(-A19/$D$12)) -> 1.2402206 | F19: =B19-E19 -> 0.0056494368
A20: 8.8e-05 | B20: 1.23653 | E20: =$D$2+1/$D$3*($D$8/(1+A20/$D$4)/SQRT(1+A20/$D$4/$D$5/$D$5)+(1-$D$8)/(1+A20/$D$6)/SQRT(1+A20/$D$6/$D$7/$D$7))*(1+$D$9*EXP(-A20/$D$10)+$D$11*EXP(-A20/$D$12)) -> 1.2401886 | F20: =B20-E20 -> -0.0036586015
A21: 9.6e-05 | B21: 1.25049 | E21: =$D$2+1/$D$3*($D$8/(1+A21/$D$4)/SQRT(1+A21/$D$4/$D$5/$D$5)+(1-$D$8)/(1+A21/$D$6)/SQRT(1+A21/$D$6/$D$7/$D$7))*(1+$D$9*EXP(-A21/$D$10)+$D$11*EXP(-A21/$D$12)) -> 1.2401567 | F21: =B21-E21 -> 0.01033331
A22: 0.000104 | B22: 1.22666 | E22: =$D$2+1/$D$3*($D$8/(1+A22/$D$4)/SQRT(1+A22/$D$4/$D$5/$D$5)+(1-$D$8)/(1+A22/$D$6)/SQRT(1+A22/$D$6/$D$7/$D$7))*(1+$D$9*EXP(-A22/$D$10)+$D$11*EXP(-A22/$D$12)) -> 1.2401248 | F22: =B22-E22 -> -0.013464829
A23: 0.000112 | B23: 1.24356 | E23: =$D$2+1/$D$3*($D$8/(1+A23/$D$4)/SQRT(1+A23/$D$4/$D$5/$D$5)+(1-$D$8)/(1+A23/$D$6)/SQRT(1+A23/$D$6/$D$7/$D$7))*(1+$D$9*EXP(-A23/$D$10)+$D$11*EXP(-A23/$D$12)) -> 1.240093 | F23: =B23-E23 -> 0.0034669819
A24: 0.00012 | B24: 1.23604 | E24: =$D$2+1/$D$3*($D$8/(1+A24/$D$4)/SQRT(1+A24/$D$4/$D$5/$D$5)+(1-$D$8)/(1+A24/$D$6)/SQRT(1+A24/$D$6/$D$7/$D$7))*(1+$D$9*EXP(-A24/$D$10)+$D$11*EXP(-A24/$D$12)) -> 1.2400613 | F24: =B24-E24 -> -0.0040212571
... A238: 13958.644 | B238: 1.00199 | E238: =$D$2+1/$D$3*($D$8/(1+A238/$D$4)/SQRT(1+A238/$D$4/$D$5/$D$5)+(1-$D$8)/(1+A238/$D$6)/SQRT(1+A238/$D$6/$D$7/$D$7))*(1+$D$9*EXP(-A238/$D$10)+$D$11*EXP(-A238/$D$12)) -> 1.0002464 | F238: =B238-E238 -> 0.0017435971
A239: 15032.386 | B239: 1.00191
A240: 16106.127 | B240: 1.00222
A241: 17179.869 | B241: 1.00228
A242: 19327.353 | B242: 1.00277
A243: 21474.836 | B243: 1.00262
A244: 23622.32 | B244: 1.0031
A245: 25769.804 | B245: 1.00386
A246: 27917.287 | B246: 0.995913

Sheet 1_Rh110 in buffer
A1: Corr.Time [ms] | B1: Rh110 | C1: Parameters | E1: model f | F1: res | G1: chi2 | J1: Count rate [kHz] | L1: kcpm
A2: 4e-06 | B2: 1.15071 | C2: offset | D2: 0.99996179 | E2: =$D$2+1/$D$3*($D$8/(1+A2/$D$4)/SQRT(1+A2/$D$4/$D$5/$D$5)+(1-$D$8)/(1+A2/$D$6)/SQRT(1+A2/$D$6/$D$7/$D$7))*(1+$D$9*EXP(-A2/$D$10)+$D$11*EXP(-A2/$D$12)) -> 1.2462519 | F2: =B2-E2 -> -0.095541858 | G2: =SUMSQ(F$4:F$190) -> 0.0025743775 | I2: Ch.1 | J2: 108.1 | L2: =(J2+J3)/D3 -> 50.306431
A3: 8e-06 | B3: 1.20548 | C3: N | D3: 4.2598928 | E3: =$D$2+1/$D$3*($D$8/(1+A3/$D$4)/SQRT(1+A3/$D$4/$D$5/$D$5)+(1-$D$8)/(1+A3/$D$6)/SQRT(1+A3/$D$6/$D$7/$D$7))*(1+$D$9*EXP(-A3/$D$10)+$D$11*EXP(-A3/$D$12)) -> 1.2462211 | F3: =B3-E3 -> -0.040741146 | I3: Ch.2 | J3: 106.2
A4: 1.2e-05 | B4: 1.24713 | C4: tD1 [ms] | D4: 0.18926186 | E4: =$D$2+1/$D$3*($D$8/(1+A4/$D$4)/SQRT(1+A4/$D$4/$D$5/$D$5)+(1-$D$8)/(1+A4/$D$6)/SQRT(1+A4/$D$6/$D$7/$D$7))*(1+$D$9*EXP(-A4/$D$10)+$D$11*EXP(-A4/$D$12)) -> 1.2461905 | F4: =B4-E4 -> 0.00093950792
A5: 1.6e-05 | B5: 1.23943 | C5: Zo/Wo | D5: 5.5740388 | E5: =$D$2+1/$D$3*($D$8/(1+A5/$D$4)/SQRT(1+A5/$D$4/$D$5/$D$5)+(1-$D$8)/(1+A5/$D$6)/SQRT(1+A5/$D$6/$D$7/$D$7))*(1+$D$9*EXP(-A5/$D$10)+$D$11*EXP(-A5/$D$12)) -> 1.2461599 | F5: =B5-E5 -> -0.0067298949
A6: 2e-05 | B6: 1.2675 | C6: tD2 [ms] | D6: 1.38 | E6: =$D$2+1/$D$3*($D$8/(1+A6/$D$4)/SQRT(1+A6/$D$4/$D$5/$D$5)+(1-$D$8)/(1+A6/$D$6)/SQRT(1+A6/$D$6/$D$7/$D$7))*(1+$D$9*EXP(-A6/$D$10)+$D$11*EXP(-A6/$D$12)) -> 1.2461294 | F6: =B6-E6 -> 0.021370645
A7: 2.4e-05 | B7: 1.2455 | C7: Zo/Wo | D7: =D5 -> 5.5740388 | E7: =$D$2+1/$D$3*($D$8/(1+A7/$D$4)/SQRT(1+A7/$D$4/$D$5/$D$5)+(1-$D$8)/(1+A7/$D$6)/SQRT(1+A7/$D$6/$D$7/$D$7))*(1+$D$9*EXP(-A7/$D$10)+$D$11*EXP(-A7/$D$12)) -> 1.2460989 | F7: =B7-E7 -> -0.00059887147
A8: 2.8e-05 | B8: 1.24179 | C8: x1 | D8: 1 | E8: =$D$2+1/$D$3*($D$8/(1+A8/$D$4)/SQRT(1+A8/$D$4/$D$5/$D$5)+(1-$D$8)/(1+A8/$D$6)/SQRT(1+A8/$D$6/$D$7/$D$7))*(1+$D$9*EXP(-A8/$D$10)+$D$11*EXP(-A8/$D$12)) -> 1.2460684 | F8: =B8-E8 -> -0.004278445
A9: 3.2e-05 | B9: 1.24206 | C9: KT | D9: 0.049300355 | E9: =$D$2+1/$D$3*($D$8/(1+A9/$D$4)/SQRT(1+A9/$D$4/$D$5/$D$5)+(1-$D$8)/(1+A9/$D$6)/SQRT(1+A9/$D$6/$D$7/$D$7))*(1+$D$9*EXP(-A9/$D$10)+$D$11*EXP(-A9/$D$12)) -> 1.2460381 | F9: =B9-E9 -> -0.0039780752
A10: 3.6e-05 | B10: 1.25229 | C10: tT [ms] | D10: 0.0018148189 | E10: =$D$2+1/$D$3*($D$8/(1+A10/$D$4)/SQRT(1+A10/$D$4/$D$5/$D$5)+(1-$D$8)/(1+A10/$D$6)/SQRT(1+A10/$D$6/$D$7/$D$7))*(1+$D$9*EXP(-A10/$D$10)+$D$11*EXP(-A10/$D$12)) -> 1.2460078 | F10: =B10-E10 -> 0.0062822381
A11: 4e-05 | B11: 1.22377 | C11: KR | D11: 0 | E11: =$D$2+1/$D$3*($D$8/(1+A11/$D$4)/SQRT(1+A11/$D$4/$D$5/$D$5)+(1-$D$8)/(1+A11/$D$6)/SQRT(1+A11/$D$6/$D$7/$D$7))*(1+$D$9*EXP(-A11/$D$10)+$D$11*EXP(-A11/$D$12)) -> 1.2459775 | F11: =B11-E11 -> -0.022207505
A12: 4.4e-05 | B12: 1.24949 | C12: tR [ms] | D12: 2.0644404e-05 | E12: =$D$2+1/$D$3*($D$8/(1+A12/$D$4)/SQRT(1+A12/$D$4/$D$5/$D$5)+(1-$D$8)/(1+A12/$D$6)/SQRT(1+A12/$D$6/$D$7/$D$7))*(1+$D$9*EXP(-A12/$D$10)+$D$11*EXP(-A12/$D$12)) -> 1.2459473 | F12: =B12-E12 -> 0.0035426956
A13: 4.8e-05 | B13: 1.23699 | E13: =$D$2+1/$D$3*($D$8/(1+A13/$D$4)/SQRT(1+A13/$D$4/$D$5/$D$5)+(1-$D$8)/(1+A13/$D$6)/SQRT(1+A13/$D$6/$D$7/$D$7))*(1+$D$9*EXP(-A13/$D$10)+$D$11*EXP(-A13/$D$12)) -> 1.2459172 | F13: =B13-E13 -> -0.0089271599
A14: 5.2e-05 | B14: 1.23228 | E14: =$D$2+1/$D$3*($D$8/(1+A14/$D$4)/SQRT(1+A14/$D$4/$D$5/$D$5)+(1-$D$8)/(1+A14/$D$6)/SQRT(1+A14/$D$6/$D$7/$D$7))*(1+$D$9*EXP(-A14/$D$10)+$D$11*EXP(-A14/$D$12)) -> 1.2458871 | F14: =B14-E14 -> -0.013607072
A15: 5.6e-05 | B15: 1.26841 | E15: =$D$2+1/$D$3*($D$8/(1+A15/$D$4)/SQRT(1+A15/$D$4/$D$5/$D$5)+(1-$D$8)/(1+A15/$D$6)/SQRT(1+A15/$D$6/$D$7/$D$7))*(1+$D$9*EXP(-A15/$D$10)+$D$11*EXP(-A15/$D$12)) -> 1.245857 | F15: =B15-E15 -> 0.022552961
A16: 6e-05 | B16: 1.24894 | E16: =$D$2+1/$D$3*($D$8/(1+A16/$D$4)/SQRT(1+A16/$D$4/$D$5/$D$5)+(1-$D$8)/(1+A16/$D$6)/SQRT(1+A16/$D$6/$D$7/$D$7))*(1+$D$9*EXP(-A16/$D$10)+$D$11*EXP(-A16/$D$12)) -> 1.2458271 | F16: =B16-E16 -> 0.0031129377
A17: 6.4e-05 | B17: 1.24536 | E17: =$D$2+1/$D$3*($D$8/(1+A17/$D$4)/SQRT(1+A17/$D$4/$D$5/$D$5)+(1-$D$8)/(1+A17/$D$6)/SQRT(1+A17/$D$6/$D$7/$D$7))*(1+$D$9*EXP(-A17/$D$10)+$D$11*EXP(-A17/$D$12)) -> 1.2457971 | F17: =B17-E17 -> -0.00043714118
A18: 7.2e-05 | B18: 1.25922 | E18: =$D$2+1/$D$3*($D$8/(1+A18/$D$4)/SQRT(1+A18/$D$4/$D$5/$D$5)+(1-$D$8)/(1+A18/$D$6)/SQRT(1+A18/$D$6/$D$7/$D$7))*(1+$D$9*EXP(-A18/$D$10)+$D$11*EXP(-A18/$D$12)) -> 1.2457375 | F18: =B18-E18 -> 0.013482534
A19: 8e-05 | B19: 1.2517 | E19: =$D$2+1/$D$3*($D$8/(1+A19/$D$4)/SQRT(1+A19/$D$4/$D$5/$D$5)+(1-$D$8)/(1+A19/$D$6)/SQRT(1+A19/$D$6/$D$7/$D$7))*(1+$D$9*EXP(-A19/$D$10)+$D$11*EXP(-A19/$D$12)) -> 1.245678 | F19: =B19-E19 -> 0.006021989
A20: 8.8e-05 | B20: 1.24713 | E20: =$D$2+1/$D$3*($D$8/(1+A20/$D$4)/SQRT(1+A20/$D$4/$D$5/$D$5)+(1-$D$8)/(1+A20/$D$6)/SQRT(1+A20/$D$6/$D$7/$D$7))*(1+$D$9*EXP(-A20/$D$10)+$D$11*EXP(-A20/$D$12)) -> 1.2456188 | F20: =B20-E20 -> 0.0015112233
A21: 9.6e-05 | B21: 1.24586 | E21: =$D$2+1/$D$3*($D$8/(1+A21/$D$4)/SQRT(1+A21/$D$4/$D$5/$D$5)+(1-$D$8)/(1+A21/$D$6)/SQRT(1+A21/$D$6/$D$7/$D$7))*(1+$D$9*EXP(-A21/$D$10)+$D$11*EXP(-A21/$D$12)) -> 1.2455598 | F21: =B21-E21 -> 0.00030023847
A22: 0.000104 | B22: 1.24066 | E22: =$D$2+1/$D$3*($D$8/(1+A22/$D$4)/SQRT(1+A22/$D$4/$D$5/$D$5)+(1-$D$8)/(1+A22/$D$6)/SQRT(1+A22/$D$6/$D$7/$D$7))*(1+$D$9*EXP(-A22/$D$10)+$D$11*EXP(-A22/$D$12)) -> 1.245501 | F22: =B22-E22 -> -0.0048409646
A23: 0.000112 | B23: 1.24029 | E23: =$D$2+1/$D$3*($D$8/(1+A23/$D$4)/SQRT(1+A23/$D$4/$D$5/$D$5)+(1-$D$8)/(1+A23/$D$6)/SQRT(1+A23/$D$6/$D$7/$D$7))*(1+$D$9*EXP(-A23/$D$10)+$D$11*EXP(-A23/$D$12)) -> 1.2454424 | F23: =B23-E23 -> -0.005152385
A24: 0.00012 | B24: 1.24129 | E24: =$D$2+1/$D$3*($D$8/(1+A24/$D$4)/SQRT(1+A24/$D$4/$D$5/$D$5)+(1-$D$8)/(1+A24/$D$6)/SQRT(1+A24/$D$6/$D$7/$D$7))*(1+$D$9*EXP(-A24/$D$10)+$D$11*EXP(-A24/$D$12)) -> 1.245384 | F24: =B24-E24 -> -0.0040940217
... A238: 13958.644 | B238: 1.00245 | E238: =$D$2+1/$D$3*($D$8/(1+A238/$D$4)/SQRT(1+A238/$D$4/$D$5/$D$5)+(1-$D$8)/(1+A238/$D$6)/SQRT(1+A238/$D$6/$D$7/$D$7))*(1+$D$9*EXP(-A238/$D$10)+$D$11*EXP(-A238/$D$12)) -> 0.99996185 | F238: =B238-E238 -> 0.0024881456
A239: 15032.386 | B239: 1.00242
A240: 16106.127 | B240: 1.00225
A241: 17179.869 | B241: 1.0029
A242: 19327.353 | B242: 1.00323
A243: 21474.836 | B243: 1.00393
A244: 23622.32 | B244: 1.00391
A245: 25769.804 | B245: 1.00388
A246: 27917.287 | B246: 1.00456

Sheet 2_Rh110 in buffer
A1: Corr.Time [ms] | B1: Rh110 | C1: Parameters | E1: model f | F1: res | G1: chi2 | J1: Count rate [kHz] | L1: kcpm
A2: 4e-06 | B2: 1.16395 | C2: offset | D2: 1.0001378 | E2: =$D$2+1/$D$3*($D$8/(1+A2/$D$4)/SQRT(1+A2/$D$4/$D$5/$D$5)+(1-$D$8)/(1+A2/$D$6)/SQRT(1+A2/$D$6/$D$7/$D$7))*(1+$D$9*EXP(-A2/$D$10)+$D$11*EXP(-A2/$D$12)) -> 1.2449452 | F2: =B2-E2 -> -0.080995177 | G2: =SUMSQ(F$4:F$190) -> 0.0019716823 | I2: Ch.1 | J2: 107.5 | L2: =(J2+J3)/D3 -> 49.395907
A3: 8e-06 | B3: 1.22733 | C3: N | D3: 4.3141226 | E3: =$D$2+1/$D$3*($D$8/(1+A3/$D$4)/SQRT(1+A3/$D$4/$D$5/$D$5)+(1-$D$8)/(1+A3/$D$6)/SQRT(1+A3/$D$6/$D$7/$D$7))*(1+$D$9*EXP(-A3/$D$10)+$D$11*EXP(-A3/$D$12)) -> 1.2449156 | F3: =B3-E3 -> -0.017585639 | I3: Ch.2 | J3: 105.6
A4: 1.2e-05 | B4: 1.22623 | C4: tD1 [ms] | D4: 0.18923392 | E4: =$D$2+1/$D$3*($D$8/(1+A4/$D$4)/SQRT(1+A4/$D$4/$D$5/$D$5)+(1-$D$8)/(1+A4/$D$6)/SQRT(1+A4/$D$6/$D$7/$D$7))*(1+$D$9*EXP(-A4/$D$10)+$D$11*EXP(-A4/$D$12)) -> 1.2448861 | F4: =B4-E4 -> -0.018656147
A5: 1.6e-05 | B5: 1.25041 | C5: Zo/Wo | D5: 6.4166893 | E5: =$D$2+1/$D$3*($D$8/(1+A5/$D$4)/SQRT(1+A5/$D$4/$D$5/$D$5)+(1-$D$8)/(1+A5/$D$6)/SQRT(1+A5/$D$6/$D$7/$D$7))*(1+$D$9*EXP(-A5/$D$10)+$D$11*EXP(-A5/$D$12)) -> 1.2448567 | F5: =B5-E5 -> 0.0055532978
A6: 2e-05 | B6: 1.24922 | C6: tD2 [ms] | D6: 1.38 | E6: =$D$2+1/$D$3*($D$8/(1+A6/$D$4)/SQRT(1+A6/$D$4/$D$5/$D$5)+(1-$D$8)/(1+A6/$D$6)/SQRT(1+A6/$D$6/$D$7/$D$7))*(1+$D$9*EXP(-A6/$D$10)+$D$11*EXP(-A6/$D$12)) -> 1.2448273 | F6: =B6-E6 -> 0.0043926966
A7: 2.4e-05 | B7: 1.25738 | C7: Zo/Wo | D7: =D5 -> 6.4166893 | E7: =$D$2+1/$D$3*($D$8/(1+A7/$D$4)/SQRT(1+A7/$D$4/$D$5/$D$5)+(1-$D$8)/(1+A7/$D$6)/SQRT(1+A7/$D$6/$D$7/$D$7))*(1+$D$9*EXP(-A7/$D$10)+$D$11*EXP(-A7/$D$12)) -> 1.244798 | F7: =B7-E7 -> 0.012582049
A8: 2.8e-05 | B8: 1.24006 | C8: x1 | D8: 1 | E8: =$D$2+1/$D$3*($D$8/(1+A8/$D$4)/SQRT(1+A8/$D$4/$D$5/$D$5)+(1-$D$8)/(1+A8/$D$6)/SQRT(1+A8/$D$6/$D$7/$D$7))*(1+$D$9*EXP(-A8/$D$10)+$D$11*EXP(-A8/$D$12)) -> 1.2447686 | F8: =B8-E8 -> -0.004708645
A9: 3.2e-05 | B9: 1.25848 | C9: KT | D9: 0.056256508 | E9: =$D$2+1/$D$3*($D$8/(1+A9/$D$4)/SQRT(1+A9/$D$4/$D$5/$D$5)+(1-$D$8)/(1+A9/$D$6)/SQRT(1+A9/$D$6/$D$7/$D$7))*(1+$D$9*EXP(-A9/$D$10)+$D$11*EXP(-A9/$D$12)) -> 1.2447394 | F9: =B9-E9 -> 0.013740615
A10: 3.6e-05 | B10: 1.24913 | C10: tT [ms] | D10: 0.0021403234 | E10: =$D$2+1/$D$3*($D$8/(1+A10/$D$4)/SQRT(1+A10/$D$4/$D$5/$D$5)+(1-$D$8)/(1+A10/$D$6)/SQRT(1+A10/$D$6/$D$7/$D$7))*(1+$D$9*EXP(-A10/$D$10)+$D$11*EXP(-A10/$D$12)) -> 1.2447102 | F10: =B10-E10 -> 0.0044198286
A11: 4e-05 | B11: 1.23942 | C11: KR | D11: 0 | E11: =$D$2+1/$D$3*($D$8/(1+A11/$D$4)/SQRT(1+A11/$D$4/$D$5/$D$5)+(1-$D$8)/(1+A11/$D$6)/SQRT(1+A11/$D$6/$D$7/$D$7))*(1+$D$9*EXP(-A11/$D$10)+$D$11*EXP(-A11/$D$12)) -> 1.244681 | F11: =B11-E11 -> -0.0052610036
A12: 4.4e-05 | B12: 1.24501 | C12: tR [ms] | D12: 2.0644404e-05 | E12: =$D$2+1/$D$3*($D$8/(1+A12/$D$4)/SQRT(1+A12/$D$4/$D$5/$D$5)+(1-$D$8)/(1+A12/$D$6)/SQRT(1+A12/$D$6/$D$7/$D$7))*(1+$D$9*EXP(-A12/$D$10)+$D$11*EXP(-A12/$D$12)) -> 1.2446519 | F12: =B12-E12 -> 0.0003581182
A13: 4.8e-05 | B13: 1.24144 | E13: =$D$2+1/$D$3*($D$8/(1+A13/$D$4)/SQRT(1+A13/$D$4/$D$5/$D$5)+(1-$D$8)/(1+A13/$D$6)/SQRT(1+A13/$D$6/$D$7/$D$7))*(1+$D$9*EXP(-A13/$D$10)+$D$11*EXP(-A13/$D$12)) -> 1.2446228 | F13: =B13-E13 -> -0.0031828058
A14: 5.2e-05 | B14: 1.24648 | E14: =$D$2+1/$D$3*($D$8/(1+A14/$D$4)/SQRT(1+A14/$D$4/$D$5/$D$5)+(1-$D$8)/(1+A14/$D$6)/SQRT(1+A14/$D$6/$D$7/$D$7))*(1+$D$9*EXP(-A14/$D$10)+$D$11*EXP(-A14/$D$12)) -> 1.2445938 | F14: =B14-E14 -> 0.0018862243
A15: 5.6e-05 | B15: 1.23155 | E15: =$D$2+1/$D$3*($D$8/(1+A15/$D$4)/SQRT(1+A15/$D$4/$D$5/$D$5)+(1-$D$8)/(1+A15/$D$6)/SQRT(1+A15/$D$6/$D$7/$D$7))*(1+$D$9*EXP(-A15/$D$10)+$D$11*EXP(-A15/$D$12)) -> 1.2445648 | F15: =B15-E15 -> -0.013014791
A16: 6e-05 | B16: 1.26315 | E16: =$D$2+1/$D$3*($D$8/(1+A16/$D$4)/SQRT(1+A16/$D$4/$D$5/$D$5)+(1-$D$8)/(1+A16/$D$6)/SQRT(1+A16/$D$6/$D$7/$D$7))*(1+$D$9*EXP(-A16/$D$10)+$D$11*EXP(-A16/$D$12)) -> 1.2445359 | F16: =B16-E16 -> 0.018614148
A17: 6.4e-05 | B17: 1.24918 | E17: =$D$2+1/$D$3*($D$8/(1+A17/$D$4)/SQRT(1+A17/$D$4/$D$5/$D$5)+(1-$D$8)/(1+A17/$D$6)/SQRT(1+A17/$D$6/$D$7/$D$7))*(1+$D$9*EXP(-A17/$D$10)+$D$11*EXP(-A17/$D$12)) -> 1.244507 | F17: =B17-E17 -> 0.0046730412
A18: 7.2e-05 | B18: 1.24648 | E18: =$D$2+1/$D$3*($D$8/(1+A18/$D$4)/SQRT(1+A18/$D$4/$D$5/$D$5)+(1-$D$8)/(1+A18/$D$6)/SQRT(1+A18/$D$6/$D$7/$D$7))*(1+$D$9*EXP(-A18/$D$10)+$D$11*EXP(-A18/$D$12)) -> 1.2444493 | F18: =B18-E18 -> 0.0020306919
A19: 8e-05 | B19: 1.24442 | E19: =$D$2+1/$D$3*($D$8/(1+A19/$D$4)/SQRT(1+A19/$D$4/$D$5/$D$5)+(1-$D$8)/(1+A19/$D$6)/SQRT(1+A19/$D$6/$D$7/$D$7))*(1+$D$9*EXP(-A19/$D$10)+$D$11*EXP(-A19/$D$12)) -> 1.2443918 | F19: =B19-E19 -> 2.8161522e-05
A20: 8.8e-05 | B20: 1.23668 | E20: =$D$2+1/$D$3*($D$8/(1+A20/$D$4)/SQRT(1+A20/$D$4/$D$5/$D$5)+(1-$D$8)/(1+A20/$D$6)/SQRT(1+A20/$D$6/$D$7/$D$7))*(1+$D$9*EXP(-A20/$D$10)+$D$11*EXP(-A20/$D$12)) -> 1.2443345 | F20: =B20-E20 -> -0.0076545491
A21: 9.6e-05 | B21: 1.24854 | E21: =$D$2+1/$D$3*($D$8/(1+A21/$D$4)/SQRT(1+A21/$D$4/$D$5/$D$5)+(1-$D$8)/(1+A21/$D$6)/SQRT(1+A21/$D$6/$D$7/$D$7))*(1+$D$9*EXP(-A21/$D$10)+$D$11*EXP(-A21/$D$12)) -> 1.2442774 | F21: =B21-E21 -> 0.0042625606
A22: 0.000104 | B22: 1.24474 | E22: =$D$2+1/$D$3*($D$8/(1+A22/$D$4)/SQRT(1+A22/$D$4/$D$5/$D$5)+(1-$D$8)/(1+A22/$D$6)/SQRT(1+A22/$D$6/$D$7/$D$7))*(1+$D$9*EXP(-A22/$D$10)+$D$11*EXP(-A22/$D$12)) -> 1.2442205 | F22: =B22-E22 -> 0.00051949129
A23: 0.000112 | B23: 1.24803 | E23: =$D$2+1/$D$3*($D$8/(1+A23/$D$4)/SQRT(1+A23/$D$4/$D$5/$D$5)+(1-$D$8)/(1+A23/$D$6)/SQRT(1+A23/$D$6/$D$7/$D$7))*(1+$D$9*EXP(-A23/$D$10)+$D$11*EXP(-A23/$D$12)) -> 1.2441638 | F23: =B23-E23 -> 0.0038662437
A24: 0.00012 | B24: 1.23269 | E24: =$D$2+1/$D$3*($D$8/(1+A24/$D$4)/SQRT(1+A24/$D$4/$D$5/$D$5)+(1-$D$8)/(1+A24/$D$6)/SQRT(1+A24/$D$6/$D$7/$D$7))*(1+$D$9*EXP(-A24/$D$10)+$D$11*EXP(-A24/$D$12)) -> 1.2441072 | F24: =B24-E24 -> -0.011417181
... A238: 13958.644 | B238: 0.995283 | E238: =$D$2+1/$D$3*($D$8/(1+A238/$D$4)/SQRT(1+A238/$D$4/$D$5/$D$5)+(1-$D$8)/(1+A238/$D$6)/SQRT(1+A238/$D$6/$D$7/$D$7))*(1+$D$9*EXP(-A238/$D$10)+$D$11*EXP(-A238/$D$12)) -> 1.0001379 | F238: =B238-E238 -> -0.0048549132
A239: 15032.386 | B239: 0.995564
A240: 16106.127 | B240: 0.995953
A241: 17179.869 | B241: 0.996521
A242: 19327.353 | B242: 0.996504
A243: 21474.836 | B243: 0.997232
A244: 23622.32 | B244: 0.997469
A245: 25769.804 | B245: 0.998199
A246: 27917.287 | B246: 0.99879

Sheet 1_EGFP
A1: Corr.Time [ms] | B1: gfp2 | C1: Parameters | E1: model f | F1: res | G1: chi2 | J1: Count rate [kHz] | L1: kcpm
A2: 4e-06 | B2: 1.36278 | C2: offset | D2: 1.0034457 | E2: =$D$2+1/$D$3*($D$8/(1+A2/$D$4)/SQRT(1+A2/$D$4/$D$5/$D$5)+(1-$D$8)/(1+A2/$D$6)/SQRT(1+A2/$D$6/$D$7/$D$7))*(1+$D$9*EXP(-A2/$D$10)+$D$11*EXP(-A2/$D$12)) -> 1.4772278 | F2: =B2-E2 -> -0.11444782 | G2: =SUMSQ(F$3:F$190) -> 0.0079216442 | I2: Ch.1 | J2: 34.96 | L2: =(J2+J3)/D3 -> 31.608188
A3: 8e-06 | B3: 1.45004 | C3: N | D3: 3.4478408 | E3: =$D$2+1/$D$3*($D$8/(1+A3/$D$4)/SQRT(1+A3/$D$4/$D$5/$D$5)+(1-$D$8)/(1+A3/$D$6)/SQRT(1+A3/$D$6/$D$7/$D$7))*(1+$D$9*EXP(-A3/$D$10)+$D$11*EXP(-A3/$D$12)) -> 1.4553914 | F3: =B3-E3 -> -0.0053513887 | I3: Ch.2 | J3: 74.02
A4: 1.2e-05 | B4: 1.44122 | C4: tD1 [ms] | D4: 0.68635908 | E4: =$D$2+1/$D$3*($D$8/(1+A4/$D$4)/SQRT(1+A4/$D$4/$D$5/$D$5)+(1-$D$8)/(1+A4/$D$6)/SQRT(1+A4/$D$6/$D$7/$D$7))*(1+$D$9*EXP(-A4/$D$10)+$D$11*EXP(-A4/$D$12)) -> 1.4383511 | F4: =B4-E4 -> 0.0028688866
A5: 1.6e-05 | B5: 1.41469 | C5: Zo/Wo | D5: =('1_Rh110 in buffer'!D5+'2_Rh110 in buffer'!D5)/2 -> 5.995364 | E5: =$D$2+1/$D$3*($D$8/(1+A5/$D$4)/SQRT(1+A5/$D$4/$D$5/$D$5)+(1-$D$8)/(1+A5/$D$6)/SQRT(1+A5/$D$6/$D$7/$D$7))*(1+$D$9*EXP(-A5/$D$10)+$D$11*EXP(-A5/$D$12)) -> 1.4250471 | F5: =B5-E5 -> -0.010357099
A6: 2e-05 | B6: 1.44524 | C6: tD2 [ms] | D6: 1.38 | E6: =$D$2+1/$D$3*($D$8/(1+A6/$D$4)/SQRT(1+A6/$D$4/$D$5/$D$5)+(1-$D$8)/(1+A6/$D$6)/SQRT(1+A6/$D$6/$D$7/$D$7))*(1+$D$9*EXP(-A6/$D$10)+$D$11*EXP(-A6/$D$12)) -> 1.4146537 | F6: =B6-E6 -> 0.030586315
A7: 2.4e-05 | B7: 1.41908 | C7: Zo/Wo | D7: =('1_Rh110 in buffer'!D5+'2_Rh110 in buffer'!D5)/2 -> 5.995364 | E7: =$D$2+1/$D$3*($D$8/(1+A7/$D$4)/SQRT(1+A7/$D$4/$D$5/$D$5)+(1-$D$8)/(1+A7/$D$6)/SQRT(1+A7/$D$6/$D$7/$D$7))*(1+$D$9*EXP(-A7/$D$10)+$D$11*EXP(-A7/$D$12)) -> 1.4065277 | F7: =B7-E7 -> 0.01255232
A8: 2.8e-05 | B8: 1.38174 | C8: x1 | D8: 1 | E8: =$D$2+1/$D$3*($D$8/(1+A8/$D$4)/SQRT(1+A8/$D$4/$D$5/$D$5)+(1-$D$8)/(1+A8/$D$6)/SQRT(1+A8/$D$6/$D$7/$D$7))*(1+$D$9*EXP(-A8/$D$10)+$D$11*EXP(-A8/$D$12)) -> 1.400168 | F8: =B8-E8 -> -0.018428037
A9: 3.2e-05 | B9: 1.38578 | C9: KT | D9: 0.29542475 | E9: =$D$2+1/$D$3*($D$8/(1+A9/$D$4)/SQRT(1+A9/$D$4/$D$5/$D$5)+(1-$D$8)/(1+A9/$D$6)/SQRT(1+A9/$D$6/$D$7/$D$7))*(1+$D$9*EXP(-A9/$D$10)+$D$11*EXP(-A9/$D$12)) -> 1.3951844 | F9: =B9-E9 -> -0.0094044377
A10: 3.6e-05 | B10: 1.37006 | C10: tT [ms] | D10: 0.0025729704 | E10: =$D$2+1/$D$3*($D$8/(1+A10/$D$4)/SQRT(1+A10/$D$4/$D$5/$D$5)+(1-$D$8)/(1+A10/$D$6)/SQRT(1+A10/$D$6/$D$7/$D$7))*(1+$D$9*EXP(-A10/$D$10)+$D$11*EXP(-A10/$D$12)) -> 1.3912728 | F10: =B10-E10 -> -0.021212825
A11: 4e-05 | B11: 1.39058 | C11: KR | D11: 0.43461665 | E11: =$D$2+1/$D$3*($D$8/(1+A11/$D$4)/SQRT(1+A11/$D$4/$D$5/$D$5)+(1-$D$8)/(1+A11/$D$6)/SQRT(1+A11/$D$6/$D$7/$D$7))*(1+$D$9*EXP(-A11/$D$10)+$D$11*EXP(-A11/$D$12)) -> 1.3881963 | F11: =B11-E11 -> 0.0023836626
A12: 4.4e-05 | B12: 1.3926 | C12: tR [ms] | D12: 1.6016927e-05 | E12: =$D$2+1/$D$3*($D$8/(1+A12/$D$4)/SQRT(1+A12/$D$4/$D$5/$D$5)+(1-$D$8)/(1+A12/$D$6)/SQRT(1+A12/$D$6/$D$7/$D$7))*(1+$D$9*EXP(-A12/$D$10)+$D$11*EXP(-A12/$D$12)) -> 1.3857705 | F12: =B12-E12 -> 0.0068295411
A13: 4.8e-05 | B13: 1.39258 | E13: =$D$2+1/$D$3*($D$8/(1+A13/$D$4)/SQRT(1+A13/$D$4/$D$5/$D$5)+(1-$D$8)/(1+A13/$D$6)/SQRT(1+A13/$D$6/$D$7/$D$7))*(1+$D$9*EXP(-A13/$D$10)+$D$11*EXP(-A13/$D$12)) -> 1.3838515 | F13: =B13-E13 -> 0.0087285488
A14: 5.2e-05 | B14: 1.37406 | E14: =$D$2+1/$D$3*($D$8/(1+A14/$D$4)/SQRT(1+A14/$D$4/$D$5/$D$5)+(1-$D$8)/(1+A14/$D$6)/SQRT(1+A14/$D$6/$D$7/$D$7))*(1+$D$9*EXP(-A14/$D$10)+$D$11*EXP(-A14/$D$12)) -> 1.3823273 | F14: =B14-E14 -> -0.0082673418
A15: 5.6e-05 | B15: 1.38857 | E15: =$D$2+1/$D$3*($D$8/(1+A15/$D$4)/SQRT(1+A15/$D$4/$D$5/$D$5)+(1-$D$8)/(1+A15/$D$6)/SQRT(1+A15/$D$6/$D$7/$D$7))*(1+$D$9*EXP(-A15/$D$10)+$D$11*EXP(-A15/$D$12)) -> 1.3811109 | F15: =B15-E15 -> 0.0074590959
A16: 6e-05 | B16: 1.37173 | E16: =$D$2+1/$D$3*($D$8/(1+A16/$D$4)/SQRT(1+A16/$D$4/$D$5/$D$5)+(1-$D$8)/(1+A16/$D$6)/SQRT(1+A16/$D$6/$D$7/$D$7))*(1+$D$9*EXP(-A16/$D$10)+$D$11*EXP(-A16/$D$12)) -> 1.3801342 | F16: =B16-E16 -> -0.008404188
A17: 6.4e-05 | B17: 1.3729 | E17: =$D$2+1/$D$3*($D$8/(1+A17/$D$4)/SQRT(1+A17/$D$4/$D$5/$D$5)+(1-$D$8)/(1+A17/$D$6)/SQRT(1+A17/$D$6/$D$7/$D$7))*(1+$D$9*EXP(-A17/$D$10)+$D$11*EXP(-A17/$D$12)) -> 1.3793443 | F17: =B17-E17 -> -0.0064442603
A18: 7.2e-05 | B18: 1.38553 | E18: =$D$2+1/$D$3*($D$8/(1+A18/$D$4)/SQRT(1+A18/$D$4/$D$5/$D$5)+(1-$D$8)/(1+A18/$D$6)/SQRT(1+A18/$D$6/$D$7/$D$7))*(1+$D$9*EXP(-A18/$D$10)+$D$11*EXP(-A18/$D$12)) -> 1.3781689 | F18: =B18-E18 -> 0.0073610575
A19: 8e-05 | B19: 1.38677 | E19: =$D$2+1/$D$3*($D$8/(1+A19/$D$4)/SQRT(1+A19/$D$4/$D$5/$D$5)+(1-$D$8)/(1+A19/$D$6)/SQRT(1+A19/$D$6/$D$7/$D$7))*(1+$D$9*EXP(-A19/$D$10)+$D$11*EXP(-A19/$D$12)) -> 1.3773528 | F19: =B19-E19 -> 0.009417215
A20: 8.8e-05 | B20: 1.36668 | E20: =$D$2+1/$D$3*($D$8/(1+A20/$D$4)/SQRT(1+A20/$D$4/$D$5/$D$5)+(1-$D$8)/(1+A20/$D$6)/SQRT(1+A20/$D$6/$D$7/$D$7))*(1+$D$9*EXP(-A20/$D$10)+$D$11*EXP(-A20/$D$12)) -> 1.3767549 | F20: =B20-E20 -> -0.010074898
A21: 9.6e-05 | B21: 1.39399 | E21: =$D$2+1/$D$3*($D$8/(1+A21/$D$4)/SQRT(1+A21/$D$4/$D$5/$D$5)+(1-$D$8)/(1+A21/$D$6)/SQRT(1+A21/$D$6/$D$7/$D$7))*(1+$D$9*EXP(-A21/$D$10)+$D$11*EXP(-A21/$D$12)) -> 1.3762898 | F21: =B21-E21 -> 0.017700217
A22: 0.000104 | B22: 1.38919 | E22: =$D$2+1/$D$3*($D$8/(1+A22/$D$4)/SQRT(1+A22/$D$4/$D$5/$D$5)+(1-$D$8)/(1+A22/$D$6)/SQRT(1+A22/$D$6/$D$7/$D$7))*(1+$D$9*EXP(-A22/$D$10)+$D$11*EXP(-A22/$D$12)) -> 1.3759056 | F22: =B22-E22 -> 0.013284445
A23: 0.000112 | B23: 1.37132 | E23: =$D$2+1/$D$3*($D$8/(1+A23/$D$4)/SQRT(1+A23/$D$4/$D$5/$D$5)+(1-$D$8)/(1+A23/$D$6)/SQRT(1+A23/$D$6/$D$7/$D$7))*(1+$D$9*EXP(-A23/$D$10)+$D$11*EXP(-A23/$D$12)) -> 1.3755707 | F23: =B23-E23 -> -0.0042507257
A24: 0.00012 | B24: 1.39923 | E24: =$D$2+1/$D$3*($D$8/(1+A24/$D$4)/SQRT(1+A24/$D$4/$D$5/$D$5)+(1-$D$8)/(1+A24/$D$6)/SQRT(1+A24/$D$6/$D$7/$D$7))*(1+$D$9*EXP(-A24/$D$10)+$D$11*EXP(-A24/$D$12)) -> 1.3752662 | F24: =B24-E24 -> 0.023963813
... A238: 13958.644 | B238: 0.999885 | E238: =$D$2+1/$D$3*($D$8/(1+A238/$D$4)/SQRT(1+A238/$D$4/$D$5/$D$5)+(1-$D$8)/(1+A238/$D$6)/SQRT(1+A238/$D$6/$D$7/$D$7))*(1+$D$9*EXP(-A238/$D$10)+$D$11*EXP(-A238/$D$12)) -> 1.0034463 | F238: =B238-E238 -> -0.0035612782
A239: 15032.386 | B239: 0.999071
A240: 16106.127 | B240: 0.998892
A241: 17179.869 | B241: 0.999893
A242: 19327.353 | B242: 0.999104
A243: 21474.836 | B243: 0.999789
A244: 23622.32 | B244: 0.998957
A245: 25769.804 | B245: 0.999457
A246: 27917.287 | B246: 0.99357

Sheet 2_EGFP
A1: Corr.Time [ms] | B1: gfp2 | C1: Parameters | E1: model f | F1: res | G1: chi2 | J1: Count rate [kHz] | L1: kcpm
A2: 4e-06 | B2: 1.37712 | C2: offset | D2: 1.0058236 | E2: =$D$2+1/$D$3*($D$8/(1+A2/$D$4)/SQRT(1+A2/$D$4/$D$5/$D$5)+(1-$D$8)/(1+A2/$D$6)/SQRT(1+A2/$D$6/$D$7/$D$7))*(1+$D$9*EXP(-A2/$D$10)+$D$11*EXP(-A2/$D$12)) -> 1.454981 | F2: =B2-E2 -> -0.07786103 | G2: =SUMSQ(F$3:F$190) -> 0.012570953 | I2: Ch.1 | J2: 31.63 | L2: =(J2+J3)/D3 -> 30.787446
A3: 8e-06 | B3: 1.4871 | C3: N | D3: 3.2016297 | E3: =$D$2+1/$D$3*($D$8/(1+A3/$D$4)/SQRT(1+A3/$D$4/$D$5/$D$5)+(1-$D$8)/(1+A3/$D$6)/SQRT(1+A3/$D$6/$D$7/$D$7))*(1+$D$9*EXP(-A3/$D$10)+$D$11*EXP(-A3/$D$12)) -> 1.453547 | F3: =B3-E3 -> 0.033553008 | I3: Ch.2 | J3: 66.94
A4: 1.2e-05 | B4: 1.45028 | C4: tD1 [ms] | D4: 0.70139501 | E4: =$D$2+1/$D$3*($D$8/(1+A4/$D$4)/SQRT(1+A4/$D$4/$D$5/$D$5)+(1-$D$8)/(1+A4/$D$6)/SQRT(1+A4/$D$6/$D$7/$D$7))*(1+$D$9*EXP(-A4/$D$10)+$D$11*EXP(-A4/$D$12)) -> 1.4521433 | F4: =B4-E4 -> -0.0018633499
A5: 1.6e-05 | B5: 1.47826 | C5: Zo/Wo | D5: =('1_Rh110 in buffer'!D5+'2_Rh110 in buffer'!D5)/2 -> 5.995364 | E5: =$D$2+1/$D$3*($D$8/(1+A5/$D$4)/SQRT(1+A5/$D$4/$D$5/$D$5)+(1-$D$8)/(1+A5/$D$6)/SQRT(1+A5/$D$6/$D$7/$D$7))*(1+$D$9*EXP(-A5/$D$10)+$D$11*EXP(-A5/$D$12)) -> 1.4507694 | F5: =B5-E5 -> 0.027490574
A6: 2e-05 | B6: 1.43997 | C6: tD2 [ms] | D6: 1.38 | E6: =$D$2+1/$D$3*($D$8/(1+A6/$D$4)/SQRT(1+A6/$D$4/$D$5/$D$5)+(1-$D$8)/(1+A6/$D$6)/SQRT(1+A6/$D$6/$D$7/$D$7))*(1+$D$9*EXP(-A6/$D$10)+$D$11*EXP(-A6/$D$12)) -> 1.4494246 | F6: =B6-E6 -> -0.0094545575
A7: 2.4e-05 | B7: 1.42867 | C7: Zo/Wo | D7: =('1_Rh110 in buffer'!D5+'2_Rh110 in buffer'!D5)/2 -> 5.995364 | E7: =$D$2+1/$D$3*($D$8/(1+A7/$D$4)/SQRT(1+A7/$D$4/$D$5/$D$5)+(1-$D$8)/(1+A7/$D$6)/SQRT(1+A7/$D$6/$D$7/$D$7))*(1+$D$9*EXP(-A7/$D$10)+$D$11*EXP(-A7/$D$12)) -> 1.4481081 | F7: =B7-E7 -> -0.019438098
A8: 2.8e-05 | B8: 1.47188 | C8: x1 | D8: 1 | E8: =$D$2+1/$D$3*($D$8/(1+A8/$D$4)/SQRT(1+A8/$D$4/$D$5/$D$5)+(1-$D$8)/(1+A8/$D$6)/SQRT(1+A8/$D$6/$D$7/$D$7))*(1+$D$9*EXP(-A8/$D$10)+$D$11*EXP(-A8/$D$12)) -> 1.4468194 | F8: =B8-E8 -> 0.025060584
A9: 3.2e-05 | B9: 1.44144 | C9: KT | D9: 0.24349179 | E9: =$D$2+1/$D$3*($D$8/(1+A9/$D$4)/SQRT(1+A9/$D$4/$D$5/$D$5)+(1-$D$8)/(1+A9/$D$6)/SQRT(1+A9/$D$6/$D$7/$D$7))*(1+$D$9*EXP(-A9/$D$10)+$D$11*EXP(-A9/$D$12)) -> 1.4455579 | F9: =B9-E9 -> -0.0041178906
A10: 3.6e-05 | B10: 1.44733 | C10: tT [ms] | D10: 0.0041306743 | E10: =$D$2+1/$D$3*($D$8/(1+A10/$D$4)/SQRT(1+A10/$D$4/$D$5/$D$5)+(1-$D$8)/(1+A10/$D$6)/SQRT(1+A10/$D$6/$D$7/$D$7))*(1+$D$9*EXP(-A10/$D$10)+$D$11*EXP(-A10/$D$12)) -> 1.4443229 | F10: =B10-E10 -> 0.0030070814
A11: 4e-05 | B11: 1.45224 | C11: KR | D11: 0.19923468 | E11: =$D$2+1/$D$3*($D$8/(1+A11/$D$4)/SQRT(1+A11/$D$4/$D$5/$D$5)+(1-$D$8)/(1+A11/$D$6)/SQRT(1+A11/$D$6/$D$7/$D$7))*(1+$D$9*EXP(-A11/$D$10)+$D$11*EXP(-A11/$D$12)) -> 1.4431139 | F11: =B11-E11 -> 0.0091260917
A12: 4.4e-05 | B12: 1.4164 | C12: tR [ms] | D12: 0.00017720878 | E12: =$D$2+1/$D$3*($D$8/(1+A12/$D$4)/SQRT(1+A12/$D$4/$D$5/$D$5)+(1-$D$8)/(1+A12/$D$6)/SQRT(1+A12/$D$6/$D$7/$D$7))*(1+$D$9*EXP(-A12/$D$10)+$D$11*EXP(-A12/$D$12)) -> 1.4419303 | F12: =B12-E12 -> -0.025530282
A13: 4.8e-05 | B13: 1.40216 | E13: =$D$2+1/$D$3*($D$8/(1+A13/$D$4)/SQRT(1+A13/$D$4/$D$5/$D$5)+(1-$D$8)/(1+A13/$D$6)/SQRT(1+A13/$D$6/$D$7/$D$7))*(1+$D$9*EXP(-A13/$D$10)+$D$11*EXP(-A13/$D$12)) -> 1.4407715 | F13: =B13-E13 -> -0.038611474
A14: 5.2e-05 | B14: 1.43211 | E14: =$D$2+1/$D$3*($D$8/(1+A14/$D$4)/SQRT(1+A14/$D$4/$D$5/$D$5)+(1-$D$8)/(1+A14/$D$6)/SQRT(1+A14/$D$6/$D$7/$D$7))*(1+$D$9*EXP(-A14/$D$10)+$D$11*EXP(-A14/$D$12)) -> 1.4396369 | F14: =B14-E14 -> -0.0075269313
A15: 5.6e-05 | B15: 1.45224 | E15: =$D$2+1/$D$3*($D$8/(1+A15/$D$4)/SQRT(1+A15/$D$4/$D$5/$D$5)+(1-$D$8)/(1+A15/$D$6)/SQRT(1+A15/$D$6/$D$7/$D$7))*(1+$D$9*EXP(-A15/$D$10)+$D$11*EXP(-A15/$D$12)) -> 1.4385261 | F15: =B15-E15 -> 0.013713885
A16: 6e-05 | B16: 1.40118 | E16: =$D$2+1/$D$3*($D$8/(1+A16/$D$4)/SQRT(1+A16/$D$4/$D$5/$D$5)+(1-$D$8)/(1+A16/$D$6)/SQRT(1+A16/$D$6/$D$7/$D$7))*(1+$D$9*EXP(-A16/$D$10)+$D$11*EXP(-A16/$D$12)) -> 1.4374385 | F16: =B16-E16 -> -0.036258496
A17: 6.4e-05 | B17: 1.44929 | E17: =$D$2+1/$D$3*($D$8/(1+A17/$D$4)/SQRT(1+A17/$D$4/$D$5/$D$5)+(1-$D$8)/(1+A17/$D$6)/SQRT(1+A17/$D$6/$D$7/$D$7))*(1+$D$9*EXP(-A17/$D$10)+$D$11*EXP(-A17/$D$12)) -> 1.4363736 | F17: =B17-E17 -> 0.012916442
A18: 7.2e-05 | B18: 1.43481 | E18: =$D$2+1/$D$3*($D$8/(1+A18/$D$4)/SQRT(1+A18/$D$4/$D$5/$D$5)+(1-$D$8)/(1+A18/$D$6)/SQRT(1+A18/$D$6/$D$7/$D$7))*(1+$D$9*EXP(-A18/$D$10)+$D$11*EXP(-A18/$D$12)) -> 1.4343097 | F18: =B18-E18 -> 0.00050028174
A19: 8e-05 | B19: 1.41689 | E19: =$D$2+1/$D$3*($D$8/(1+A19/$D$4)/SQRT(1+A19/$D$4/$D$5/$D$5)+(1-$D$8)/(1+A19/$D$6)/SQRT(1+A19/$D$6/$D$7/$D$7))*(1+$D$9*EXP(-A19/$D$10)+$D$11*EXP(-A19/$D$12)) -> 1.4323307 | F19: =B19-E19 -> -0.01544069
A20: 8.8e-05 | B20: 1.43555 | E20: =$D$2+1/$D$3*($D$8/(1+A20/$D$4)/SQRT(1+A20/$D$4/$D$5/$D$5)+(1-$D$8)/(1+A20/$D$6)/SQRT(1+A20/$D$6/$D$7/$D$7))*(1+$D$9*EXP(-A20/$D$10)+$D$11*EXP(-A20/$D$12)) -> 1.4304327 | F20: =B20-E20 -> 0.005117259
A21: 9.6e-05 | B21: 1.42499 | E21: =$D$2+1/$D$3*($D$8/(1+A21/$D$4)/SQRT(1+A21/$D$4/$D$5/$D$5)+(1-$D$8)/(1+A21/$D$6)/SQRT(1+A21/$D$6/$D$7/$D$7))*(1+$D$9*EXP(-A21/$D$10)+$D$11*EXP(-A21/$D$12)) -> 1.4286123 | F21: =B21-E21 -> -0.0036223032
A22: 0.000104 | B22: 1.40732 | E22: =$D$2+1/$D$3*($D$8/(1+A22/$D$4)/SQRT(1+A22/$D$4/$D$5/$D$5)+(1-$D$8)/(1+A22/$D$6)/SQRT(1+A22/$D$6/$D$7/$D$7))*(1+$D$9*EXP(-A22/$D$10)+$D$11*EXP(-A22/$D$12)) -> 1.426866 | F22: =B22-E22 -> -0.019545966
A23: 0.000112 | B23: 1.42376 | E23: =$D$2+1/$D$3*($D$8/(1+A23/$D$4)/SQRT(1+A23/$D$4/$D$5/$D$5)+(1-$D$8)/(1+A23/$D$6)/SQRT(1+A23/$D$6/$D$7/$D$7))*(1+$D$9*EXP(-A23/$D$10)+$D$11*EXP(-A23/$D$12)) -> 1.4251905 | F23: =B23-E23 -> -0.0014304708
A24: 0.00012 | B24: 1.44561 | E24: =$D$2+1/$D$3*($D$8/(1+A24/$D$4)/SQRT(1+A24/$D$4/$D$5/$D$5)+(1-$D$8)/(1+A24/$D$6)/SQRT(1+A24/$D$6/$D$7/$D$7))*(1+$D$9*EXP(-A24/$D$10)+$D$11*EXP(-A24/$D$12)) -> 1.4235827 | F24: =B24-E24 -> 0.0220273
... A238: 13958.644 | B238: 1.00152 | E238: =$D$2+1/$D$3*($D$8/(1+A238/$D$4)/SQRT(1+A238/$D$4/$D$5/$D$5)+(1-$D$8)/(1+A238/$D$6)/SQRT(1+A238/$D$6/$D$7/$D$7))*(1+$D$9*EXP(-A238/$D$10)+$D$11*EXP(-A238/$D$12)) -> 1.0058243 | F238: =B238-E238 -> -0.0043042838
A239: 15032.386 | B239: 1.00056
A240: 16106.127 | B240: 1.00124
A241: 17179.869 | B241: 1.00079
A242: 19327.353 | B242: 1.00124
A243: 21474.836 | B243: 1.00009
A244: 23622.32 | B244: 0.997184
A245: 25769.804 | B245: 0.995261
A246: 27917.287 | B246: 0.99365

Sheet 1_EGFP+Rh110
A1: Corr.Time [ms] | B1: mixknown1 | C1: Parameters | E1: model f | F1: res | G1: chi2 | J1: Count rate [kHz] | L1: kcpm
A2: 4e-06 | B2: 1.27936 | C2: offset | D2: 1.0017914 | E2: =$D$2+1/$D$3*($D$8/(1+A2/$D$4)/SQRT(1+A2/$D$4/$D$5/$D$5)+(1-$D$8)/(1+A2/$D$6)/SQRT(1+A2/$D$6/$D$7/$D$7))*(1+$D$9*EXP(-A2/$D$10)+$D$11*EXP(-A2/$D$12)) -> 1.3760244 | F2: =B2-E2 -> -0.096664365 | G2: =SUMSQ(F$3:F$190) -> 0.005939089 | I2: Ch.1 | J2: 53.22 | L2: =(J2+J3)/D3 -> 39.403822
A3: 8e-06 | B3: 1.35561 | C3: N | D3: 3.3788601 | E3: =$D$2+1/$D$3*($D$8/(1+A3/$D$4)/SQRT(1+A3/$D$4/$D$5/$D$5)+(1-$D$8)/(1+A3/$D$6)/SQRT(1+A3/$D$6/$D$7/$D$7))*(1+$D$9*EXP(-A3/$D$10)+$D$11*EXP(-A3/$D$12)) -> 1.3724626 | F3: =B3-E3 -> -0.016852621 | I3: Ch.2 | J3: 79.92
A4: 1.2e-05 | B4: 1.38958 | C4: tD1 [ms] | D4: =('1_Rh110 in buffer'!D4+'2_Rh110 in buffer'!D4)/2 -> 0.18924789 | E4: =$D$2+1/$D$3*($D$8/(1+A4/$D$4)/SQRT(1+A4/$D$4/$D$5/$D$5)+(1-$D$8)/(1+A4/$D$6)/SQRT(1+A4/$D$6/$D$7/$D$7))*(1+$D$9*EXP(-A4/$D$10)+$D$11*EXP(-A4/$D$12)) -> 1.3692474 | F4: =B4-E4 -> 0.020332575
A5: 1.6e-05 | B5: 1.37834 | C5: Zo/Wo | D5: =('1_Rh110 in buffer'!D5+'2_Rh110 in buffer'!D5)/2 -> 5.995364 | E5: =$D$2+1/$D$3*($D$8/(1+A5/$D$4)/SQRT(1+A5/$D$4/$D$5/$D$5)+(1-$D$8)/(1+A5/$D$6)/SQRT(1+A5/$D$6/$D$7/$D$7))*(1+$D$9*EXP(-A5/$D$10)+$D$11*EXP(-A5/$D$12)) -> 1.3663443 | F5: =B5-E5 -> 0.011995668
A6: 2e-05 | B6: 1.35781 | C6: tD2 [ms] | D6: =('1_EGFP'!D4+'2_EGFP'!D4)/2 -> 0.69387705 | E6: =$D$2+1/$D$3*($D$8/(1+A6/$D$4)/SQRT(1+A6/$D$4/$D$5/$D$5)+(1-$D$8)/(1+A6/$D$6)/SQRT(1+A6/$D$6/$D$7/$D$7))*(1+$D$9*EXP(-A6/$D$10)+$D$11*EXP(-A6/$D$12)) -> 1.3637223 | F6: =B6-E6 -> -0.0059123193
A7: 2.4e-05 | B7: 1.37418 | C7: Zo/Wo | D7: =('1_Rh110 in buffer'!D5+'2_Rh110 in buffer'!D5)/2 -> 5.995364 | E7: =$D$2+1/$D$3*($D$8/(1+A7/$D$4)/SQRT(1+A7/$D$4/$D$5/$D$5)+(1-$D$8)/(1+A7/$D$6)/SQRT(1+A7/$D$6/$D$7/$D$7))*(1+$D$9*EXP(-A7/$D$10)+$D$11*EXP(-A7/$D$12)) -> 1.3613534 | F7: =B7-E7 -> 0.01282655
A8: 2.8e-05 | B8: 1.34877 | C8: x1 | D8: 0.61894046 | E8: =$D$2+1/$D$3*($D$8/(1+A8/$D$4)/SQRT(1+A8/$D$4/$D$5/$D$5)+(1-$D$8)/(1+A8/$D$6)/SQRT(1+A8/$D$6/$D$7/$D$7))*(1+$D$9*EXP(-A8/$D$10)+$D$11*EXP(-A8/$D$12)) -> 1.3592126 | F8: =B8-E8 -> -0.010442565
A9: 3.2e-05 | B9: 1.33924 | C9: KT | D9: 0.14635727 | E9: =$D$2+1/$D$3*($D$8/(1+A9/$D$4)/SQRT(1+A9/$D$4/$D$5/$D$5)+(1-$D$8)/(1+A9/$D$6)/SQRT(1+A9/$D$6/$D$7/$D$7))*(1+$D$9*EXP(-A9/$D$10)+$D$11*EXP(-A9/$D$12)) -> 1.357277 | F9: =B9-E9 -> -0.018037007
A10: 3.6e-05 | B10: 1.34437 | C10: tT [ms] | D10: 0.0023822643 | E10: =$D$2+1/$D$3*($D$8/(1+A10/$D$4)/SQRT(1+A10/$D$4/$D$5/$D$5)+(1-$D$8)/(1+A10/$D$6)/SQRT(1+A10/$D$6/$D$7/$D$7))*(1+$D$9*EXP(-A10/$D$10)+$D$11*EXP(-A10/$D$12)) -> 1.3555264 | F10: =B10-E10 -> -0.011156371
A11: 4e-05 | B11: 1.32555 | C11: KR | D11: 0.13145847 | E11: =$D$2+1/$D$3*($D$8/(1+A11/$D$4)/SQRT(1+A11/$D$4/$D$5/$D$5)+(1-$D$8)/(1+A11/$D$6)/SQRT(1+A11/$D$6/$D$7/$D$7))*(1+$D$9*EXP(-A11/$D$10)+$D$11*EXP(-A11/$D$12)) -> 1.3539423 | F11: =B11-E11 -> -0.028392281
A12: 4.4e-05 | B12: 1.36734 | C12: tR [ms] | D12: 3.8198175e-05 | E12: =$D$2+1/$D$3*($D$8/(1+A12/$D$4)/SQRT(1+A12/$D$4/$D$5/$D$5)+(1-$D$8)/(1+A12/$D$6)/SQRT(1+A12/$D$6/$D$7/$D$7))*(1+$D$9*EXP(-A12/$D$10)+$D$11*EXP(-A12/$D$12)) -> 1.3525082 | F12: =B12-E12 -> 0.01483181
A13: 4.8e-05 | B13: 1.36661 | E13: =$D$2+1/$D$3*($D$8/(1+A13/$D$4)/SQRT(1+A13/$D$4/$D$5/$D$5)+(1-$D$8)/(1+A13/$D$6)/SQRT(1+A13/$D$6/$D$7/$D$7))*(1+$D$9*EXP(-A13/$D$10)+$D$11*EXP(-A13/$D$12)) -> 1.3512092 | F13: =B13-E13 -> 0.015400806
A14: 5.2e-05 | B14: 1.37614 | E14: =$D$2+1/$D$3*($D$8/(1+A14/$D$4)/SQRT(1+A14/$D$4/$D$5/$D$5)+(1-$D$8)/(1+A14/$D$6)/SQRT(1+A14/$D$6/$D$7/$D$7))*(1+$D$9*EXP(-A14/$D$10)+$D$11*EXP(-A14/$D$12)) -> 1.3500319 | F14: =B14-E14 -> 0.026108129
A15: 5.6e-05 | B15: 1.36025 | E15: =$D$2+1/$D$3*($D$8/(1+A15/$D$4)/SQRT(1+A15/$D$4/$D$5/$D$5)+(1-$D$8)/(1+A15/$D$6)/SQRT(1+A15/$D$6/$D$7/$D$7))*(1+$D$9*EXP(-A15/$D$10)+$D$11*EXP(-A15/$D$12)) -> 1.3489641 | F15: =B15-E15 -> 0.011285864
A16: 6e-05 | B16: 1.33997 | E16: =$D$2+1/$D$3*($D$8/(1+A16/$D$4)/SQRT(1+A16/$D$4/$D$5/$D$5)+(1-$D$8)/(1+A16/$D$6)/SQRT(1+A16/$D$6/$D$7/$D$7))*(1+$D$9*EXP(-A16/$D$10)+$D$11*EXP(-A16/$D$12)) -> 1.3479951 | F16: =B16-E16 -> -0.0080251033
A17: 6.4e-05 | B17: 1.33936 | E17: =$D$2+1/$D$3*($D$8/(1+A17/$D$4)/SQRT(1+A17/$D$4/$D$5/$D$5)+(1-$D$8)/(1+A17/$D$6)/SQRT(1+A17/$D$6/$D$7/$D$7))*(1+$D$9*EXP(-A17/$D$10)+$D$11*EXP(-A17/$D$12)) -> 1.347115 | F17: =B17-E17 -> -0.0077549702
A18: 7.2e-05 | B18: 1.34119 | E18: =$D$2+1/$D$3*($D$8/(1+A18/$D$4)/SQRT(1+A18/$D$4/$D$5/$D$5)+(1-$D$8)/(1+A18/$D$6)/SQRT(1+A18/$D$6/$D$7/$D$7))*(1+$D$9*EXP(-A18/$D$10)+$D$11*EXP(-A18/$D$12)) -> 1.345587 | F18: =B18-E18 -> -0.0043969699
A19: 8e-05 | B19: 1.34583 | E19: =$D$2+1/$D$3*($D$8/(1+A19/$D$4)/SQRT(1+A19/$D$4/$D$5/$D$5)+(1-$D$8)/(1+A19/$D$6)/SQRT(1+A19/$D$6/$D$7/$D$7))*(1+$D$9*EXP(-A19/$D$10)+$D$11*EXP(-A19/$D$12)) -> 1.3443195 | F19: =B19-E19 -> 0.0015104694
A20: 8.8e-05 | B20: 1.35561 | E20: =$D$2+1/$D$3*($D$8/(1+A20/$D$4)/SQRT(1+A20/$D$4/$D$5/$D$5)+(1-$D$8)/(1+A20/$D$6)/SQRT(1+A20/$D$6/$D$7/$D$7))*(1+$D$9*EXP(-A20/$D$10)+$D$11*EXP(-A20/$D$12)) -> 1.3432635 | F20: =B20-E20 -> 0.012346499
A21: 9.6e-05 | B21: 1.34241 | E21: =$D$2+1/$D$3*($D$8/(1+A21/$D$4)/SQRT(1+A21/$D$4/$D$5/$D$5)+(1-$D$8)/(1+A21/$D$6)/SQRT(1+A21/$D$6/$D$7/$D$7))*(1+$D$9*EXP(-A21/$D$10)+$D$11*EXP(-A21/$D$12)) -> 1.342379 | F21: =B21-E21 -> 3.0982782e-05
A22: 0.000104 | B22: 1.32799 | E22: =$D$2+1/$D$3*($D$8/(1+A22/$D$4)/SQRT(1+A22/$D$4/$D$5/$D$5)+(1-$D$8)/(1+A22/$D$6)/SQRT(1+A22/$D$6/$D$7/$D$7))*(1+$D$9*EXP(-A22/$D$10)+$D$11*EXP(-A22/$D$12)) -> 1.3416337 | F22: =B22-E22 -> -0.01364375
A23: 0.000112 | B23: 1.32983 | E23: =$D$2+1/$D$3*($D$8/(1+A23/$D$4)/SQRT(1+A23/$D$4/$D$5/$D$5)+(1-$D$8)/(1+A23/$D$6)/SQRT(1+A23/$D$6/$D$7/$D$7))*(1+$D$9*EXP(-A23/$D$10)+$D$11*EXP(-A23/$D$12)) -> 1.3410015 | F23: =B23-E23 -> -0.011171478
A24: 0.00012 | B24: 1.35072 | E24: =$D$2+1/$D$3*($D$8/(1+A24/$D$4)/SQRT(1+A24/$D$4/$D$5/$D$5)+(1-$D$8)/(1+A24/$D$6)/SQRT(1+A24/$D$6/$D$7/$D$7))*(1+$D$9*EXP(-A24/$D$10)+$D$11*EXP(-A24/$D$12)) -> 1.3404609 | F24: =B24-E24 -> 0.010259064
... A238: 13958.644 | B238: 1.00807 | E238: =$D$2+1/$D$3*($D$8/(1+A238/$D$4)/SQRT(1+A238/$D$4/$D$5/$D$5)+(1-$D$8)/(1+A238/$D$6)/SQRT(1+A238/$D$6/$D$7/$D$7))*(1+$D$9*EXP(-A238/$D$10)+$D$11*EXP(-A238/$D$12)) -> 1.0017917 | F238: =B238-E238 -> 0.0062783378
A239: 15032.386 | B239: 1.00926
A240: 16106.127 | B240: 1.01001
A241: 17179.869 | B241: 1.01078
A242: 19327.353 | B242: 1.01036
A243: 21474.836 | B243: 1.01027
A244: 23622.32 | B244: 1.00981
A245: 25769.804 | B245: 1.01007
A246: 27917.287 | B246: 1.0099

Sheet 2_EGFP+Rh110
A1: Corr.Time [ms] | B1: mixknown2 | C1: Parameters | E1: model f | F1: res | G1: chi2 | J1: Count rate [kHz] | L1: kcpm
A2: 4e-06 | B2: 1.26291 | C2: offset | D2: 1.0034042 | E2: =$D$2+1/$D$3*($D$8/(1+A2/$D$4)/SQRT(1+A2/$D$4/$D$5/$D$5)+(1-$D$8)/(1+A2/$D$6)/SQRT(1+A2/$D$6/$D$7/$D$7))*(1+$D$9*EXP(-A2/$D$10)+$D$11*EXP(-A2/$D$12)) -> 1.4015382 | F2: =B2-E2 -> -0.13862823 | G2: =SUMSQ(F$3:F$190) -> 0.0074832173 | I2: Ch.1 | J2: 50.46 | L2: =(J2+J3)/D3 -> 39.971018
A3: 8e-06 | B3: 1.40661 | C3: N | D3: 3.1092528 | E3: =$D$2+1/$D$3*($D$8/(1+A3/$D$4)/SQRT(1+A3/$D$4/$D$5/$D$5)+(1-$D$8)/(1+A3/$D$6)/SQRT(1+A3/$D$6/$D$7/$D$7))*(1+$D$9*EXP(-A3/$D$10)+$D$11*EXP(-A3/$D$12)) -> 1.3993733 | F3: =B3-E3 -> 0.0072366977 | I3: Ch.2 | J3: 73.82
A4: 1.2e-05 | B4: 1.37898 | C4: tD1 [ms] | D4: =('1_Rh110 in buffer'!D4+'2_Rh110 in buffer'!D4)/2 -> 0.18924789 | E4: =$D$2+1/$D$3*($D$8/(1+A4/$D$4)/SQRT(1+A4/$D$4/$D$5/$D$5)+(1-$D$8)/(1+A4/$D$6)/SQRT(1+A4/$D$6/$D$7/$D$7))*(1+$D$9*EXP(-A4/$D$10)+$D$11*EXP(-A4/$D$12)) -> 1.3973305 | F4: =B4-E4 -> -0.018350487
A5: 1.6e-05 | B5: 1.43228 | C5: Zo/Wo | D5: =('1_Rh110 in buffer'!D5+'2_Rh110 in buffer'!D5)/2 -> 5.995364 | E5: =$D$2+1/$D$3*($D$8/(1+A5/$D$4)/SQRT(1+A5/$D$4/$D$5/$D$5)+(1-$D$8)/(1+A5/$D$6)/SQRT(1+A5/$D$6/$D$7/$D$7))*(1+$D$9*EXP(-A5/$D$10)+$D$11*EXP(-A5/$D$12)) -> 1.3954027 | F5: =B5-E5 -> 0.036877278
A6: 2e-05 | B6: 1.40633 | C6: tD2 [ms] | D6: =('1_EGFP'!D4+'2_EGFP'!D4)/2 -> 0.69387705 | E6: =$D$2+1/$D$3*($D$8/(1+A6/$D$4)/SQRT(1+A6/$D$4/$D$5/$D$5)+(1-$D$8)/(1+A6/$D$6)/SQRT(1+A6/$D$6/$D$7/$D$7))*(1+$D$9*EXP(-A6/$D$10)+$D$11*EXP(-A6/$D$12)) -> 1.3935834 | F6: =B6-E6 -> 0.012746647
A7: 2.4e-05 | B7: 1.36113 | C7: Zo/Wo | D7: =('1_Rh110 in buffer'!D5+'2_Rh110 in buffer'!D5)/2 -> 5.995364 | E7: =$D$2+1/$D$3*($D$8/(1+A7/$D$4)/SQRT(1+A7/$D$4/$D$5/$D$5)+(1-$D$8)/(1+A7/$D$6)/SQRT(1+A7/$D$6/$D$7/$D$7))*(1+$D$9*EXP(-A7/$D$10)+$D$11*EXP(-A7/$D$12)) -> 1.3918661 | F7: =B7-E7 -> -0.030736113
A8: 2.8e-05 | B8: 1.37815 | C8: x1 | D8: 0.6355538 | E8: =$D$2+1/$D$3*($D$8/(1+A8/$D$4)/SQRT(1+A8/$D$4/$D$5/$D$5)+(1-$D$8)/(1+A8/$D$6)/SQRT(1+A8/$D$6/$D$7/$D$7))*(1+$D$9*EXP(-A8/$D$10)+$D$11*EXP(-A8/$D$12)) -> 1.3902451 | F8: =B8-E8 -> -0.012095095
A9: 3.2e-05 | B9: 1.36671 | C9: KT | D9: 0.12472827 | E9: =$D$2+1/$D$3*($D$8/(1+A9/$D$4)/SQRT(1+A9/$D$4/$D$5/$D$5)+(1-$D$8)/(1+A9/$D$6)/SQRT(1+A9/$D$6/$D$7/$D$7))*(1+$D$9*EXP(-A9/$D$10)+$D$11*EXP(-A9/$D$12)) -> 1.3887147 | F9: =B9-E9 -> -0.022004735
A10: 3.6e-05 | B10: 1.3854 | C10: tT [ms] | D10: 0.0032070869 | E10: =$D$2+1/$D$3*($D$8/(1+A10/$D$4)/SQRT(1+A10/$D$4/$D$5/$D$5)+(1-$D$8)/(1+A10/$D$6)/SQRT(1+A10/$D$6/$D$7/$D$7))*(1+$D$9*EXP(-A10/$D$10)+$D$11*EXP(-A10/$D$12)) -> 1.3872698 | F10: =B10-E10 -> -0.0018697922
A11: 4e-05 | B11: 1.3868 | C11: KR | D11: 0.12030527 | E11: =$D$2+1/$D$3*($D$8/(1+A11/$D$4)/SQRT(1+A11/$D$4/$D$5/$D$5)+(1-$D$8)/(1+A11/$D$6)/SQRT(1+A11/$D$6/$D$7/$D$7))*(1+$D$9*EXP(-A11/$D$10)+$D$11*EXP(-A11/$D$12)) -> 1.3859053 | F11: =B11-E11 -> 0.00089467348
A12: 4.4e-05 | B12: 1.37592 | C12: tR [ms] | D12: 6.7127824e-05 | E12: =$D$2+1/$D$3*($D$8/(1+A12/$D$4)/SQRT(1+A12/$D$4/$D$5/$D$5)+(1-$D$8)/(1+A12/$D$6)/SQRT(1+A12/$D$6/$D$7/$D$7))*(1+$D$9*EXP(-A12/$D$10)+$D$11*EXP(-A12/$D$12)) -> 1.3846167 | F12: =B12-E12 -> -0.0086966854
A13: 4.8e-05 | B13: 1.38931 | E13: =$D$2+1/$D$3*($D$8/(1+A13/$D$4)/SQRT(1+A13/$D$4/$D$5/$D$5)+(1-$D$8)/(1+A13/$D$6)/SQRT(1+A13/$D$6/$D$7/$D$7))*(1+$D$9*EXP(-A13/$D$10)+$D$11*EXP(-A13/$D$12)) -> 1.3833995 | F13: =B13-E13 -> 0.005910515
A14: 5.2e-05 | B14: 1.38122 | E14: =$D$2+1/$D$3*($D$8/(1+A14/$D$4)/SQRT(1+A14/$D$4/$D$5/$D$5)+(1-$D$8)/(1+A14/$D$6)/SQRT(1+A14/$D$6/$D$7/$D$7))*(1+$D$9*EXP(-A14/$D$10)+$D$11*EXP(-A14/$D$12)) -> 1.3822496 | F14: =B14-E14 -> -0.0010295953
A15: 5.6e-05 | B15: 1.42251 | E15: =$D$2+1/$D$3*($D$8/(1+A15/$D$4)/SQRT(1+A15/$D$4/$D$5/$D$5)+(1-$D$8)/(1+A15/$D$6)/SQRT(1+A15/$D$6/$D$7/$D$7))*(1+$D$9*EXP(-A15/$D$10)+$D$11*EXP(-A15/$D$12)) -> 1.3811631 | F15: =B15-E15 -> 0.041346875
A16: 6e-05 | B16: 1.37536 | E16: =$D$2+1/$D$3*($D$8/(1+A16/$D$4)/SQRT(1+A16/$D$4/$D$5/$D$5)+(1-$D$8)/(1+A16/$D$6)/SQRT(1+A16/$D$6/$D$7/$D$7))*(1+$D$9*EXP(-A16/$D$10)+$D$11*EXP(-A16/$D$12)) -> 1.3801364 | F16: =B16-E16 -> -0.0047764084
A17: 6.4e-05 | B17: 1.38666 | E17: =$D$2+1/$D$3*($D$8/(1+A17/$D$4)/SQRT(1+A17/$D$4/$D$5/$D$5)+(1-$D$8)/(1+A17/$D$6)/SQRT(1+A17/$D$6/$D$7/$D$7))*(1+$D$9*EXP(-A17/$D$10)+$D$11*EXP(-A17/$D$12)) -> 1.379166 | F17: =B17-E17 -> 0.0074940088
A18: 7.2e-05 | B18: 1.37508 | E18: =$D$2+1/$D$3*($D$8/(1+A18/$D$4)/SQRT(1+A18/$D$4/$D$5/$D$5)+(1-$D$8)/(1+A18/$D$6)/SQRT(1+A18/$D$6/$D$7/$D$7))*(1+$D$9*EXP(-A18/$D$10)+$D$11*EXP(-A18/$D$12)) -> 1.3773812 | F18: =B18-E18 -> -0.0023012279
A19: 8e-05 | B19: 1.37633 | E19: =$D$2+1/$D$3*($D$8/(1+A19/$D$4)/SQRT(1+A19/$D$4/$D$5/$D$5)+(1-$D$8)/(1+A19/$D$6)/SQRT(1+A19/$D$6/$D$7/$D$7))*(1+$D$9*EXP(-A19/$D$10)+$D$11*EXP(-A19/$D$12)) -> 1.375785 | F19: =B19-E19 -> 0.0005450026
A20: 8.8e-05 | B20: 1.38177 | E20: =$D$2+1/$D$3*($D$8/(1+A20/$D$4)/SQRT(1+A20/$D$4/$D$5/$D$5)+(1-$D$8)/(1+A20/$D$6)/SQRT(1+A20/$D$6/$D$7/$D$7))*(1+$D$9*EXP(-A20/$D$10)+$D$11*EXP(-A20/$D$12)) -> 1.3743561 | F20: =B20-E20 -> 0.0074138593
A21: 9.6e-05 | B21: 1.36699 | E21: =$D$2+1/$D$3*($D$8/(1+A21/$D$4)/SQRT(1+A21/$D$4/$D$5/$D$5)+(1-$D$8)/(1+A21/$D$6)/SQRT(1+A21/$D$6/$D$7/$D$7))*(1+$D$9*EXP(-A21/$D$10)+$D$11*EXP(-A21/$D$12)) -> 1.3730759 | F21: =B21-E21 -> -0.0060858765
A22: 0.000104 | B22: 1.36489 | E22: =$D$2+1/$D$3*($D$8/(1+A22/$D$4)/SQRT(1+A22/$D$4/$D$5/$D$5)+(1-$D$8)/(1+A22/$D$6)/SQRT(1+A22/$D$6/$D$7/$D$7))*(1+$D$9*EXP(-A22/$D$10)+$D$11*EXP(-A22/$D$12)) -> 1.3719275 | F22: =B22-E22 -> -0.0070375339
A23: 0.000112 | B23: 1.3794 | E23: =$D$2+1/$D$3*($D$8/(1+A23/$D$4)/SQRT(1+A23/$D$4/$D$5/$D$5)+(1-$D$8)/(1+A23/$D$6)/SQRT(1+A23/$D$6/$D$7/$D$7))*(1+$D$9*EXP(-A23/$D$10)+$D$11*EXP(-A23/$D$12)) -> 1.3708963 | F23: =B23-E23 -> 0.0085036844
A24: 0.00012 | B24: 1.35722 | E24: =$D$2+1/$D$3*($D$8/(1+A24/$D$4)/SQRT(1+A24/$D$4/$D$5/$D$5)+(1-$D$8)/(1+A24/$D$6)/SQRT(1+A24/$D$6/$D$7/$D$7))*(1+$D$9*EXP(-A24/$D$10)+$D$11*EXP(-A24/$D$12)) -> 1.3699691 | F24: =B24-E24 -> -0.012749087
... A238: 13958.644 | B238: 1.00093 | E238: =$D$2+1/$D$3*($D$8/(1+A238/$D$4)/SQRT(1+A238/$D$4/$D$5/$D$5)+(1-$D$8)/(1+A238/$D$6)/SQRT(1+A238/$D$6/$D$7/$D$7))*(1+$D$9*EXP(-A238/$D$10)+$D$11*EXP(-A238/$D$12)) -> 1.0034045 | F238: =B238-E238 -> -0.0024745375
A239: 15032.386 | B239: 1.00005
A240: 16106.127 | B240: 0.999517
A241: 17179.869 | B241: 0.998495
A242: 19327.353 | B242: 0.999454
A243: 21474.836 | B243: 1.00097
A244: 23622.32 | B244: 0.999655
A245: 25769.804 | B245: 0.997681
A246: 27917.287 | B246: 0.996286

Sheet 1_Alexa-488-IgG
A1: Corr.Time [ms] | B1: antibody1 | C1: Parameters | E1: model f | F1: res | G1: chi2 | J1: Count rate [kHz] | L1: kcpm
A2: 4e-06 | B2: 1.24608 | C2: offset | D2: 1.0026801 | E2: =$D$2+1/$D$3*($D$8/(1+A2/$D$4)/SQRT(1+A2/$D$4/$D$5/$D$5)+(1-$D$8)/(1+A2/$D$6)/SQRT(1+A2/$D$6/$D$7/$D$7))*(1+$D$9*EXP(-A2/$D$10)+$D$11*EXP(-A2/$D$12)) -> 1.3005185 | F2: =B2-E2 -> -0.054438466 | G2: =SUMSQ(F$4:F$190) -> 0.0016602412 | I2: Ch.1 | J2: 110.4 | L2: =(J2+J3)/D3 -> 55.687924
A3: 8e-06 | B3: 1.30478 | C3: N | D3: 4.2217412 | E3: =$D$2+1/$D$3*($D$8/(1+A3/$D$4)/SQRT(1+A3/$D$4/$D$5/$D$5)+(1-$D$8)/(1+A3/$D$6)/SQRT(1+A3/$D$6/$D$7/$D$7))*(1+$D$9*EXP(-A3/$D$10)+$D$11*EXP(-A3/$D$12)) -> 1.3002407 | F3: =B3-E3 -> 0.0045393478 | I3: Ch.2 | J3: 124.7
A4: 1.2e-05 | B4: 1.30948 | C4: tD1 [ms] | D4: 1.4245579 | E4: =$D$2+1/$D$3*($D$8/(1+A4/$D$4)/SQRT(1+A4/$D$4/$D$5/$D$5)+(1-$D$8)/(1+A4/$D$6)/SQRT(1+A4/$D$6/$D$7/$D$7))*(1+$D$9*EXP(-A4/$D$10)+$D$11*EXP(-A4/$D$12)) -> 1.2999656 | F4: =B4-E4 -> 0.0095144457
A5: 1.6e-05 | B5: 1.31062 | C5: Zo/Wo | D5: =('1_Rh110 in buffer'!D5+'2_Rh110 in buffer'!D5)/2 -> 5.995364 | E5: =$D$2+1/$D$3*($D$8/(1+A5/$D$4)/SQRT(1+A5/$D$4/$D$5/$D$5)+(1-$D$8)/(1+A5/$D$6)/SQRT(1+A5/$D$6/$D$7/$D$7))*(1+$D$9*EXP(-A5/$D$10)+$D$11*EXP(-A5/$D$12)) -> 1.2996931 | F5: =B5-E5 -> 0.010926855
A6: 2e-05 | B6: 1.30662 | C6: tD2 [ms] | D6: 1.38 | E6: =$D$2+1/$D$3*($D$8/(1+A6/$D$4)/SQRT(1+A6/$D$4/$D$5/$D$5)+(1-$D$8)/(1+A6/$D$6)/SQRT(1+A6/$D$6/$D$7/$D$7))*(1+$D$9*EXP(-A6/$D$10)+$D$11*EXP(-A6/$D$12)) -> 1.2994234 | F6: =B6-E6 -> 0.0071966014
A7: 2.4e-05 | B7: 1.30076 | C7: Zo/Wo | D7: =('1_Rh110 in buffer'!D5+'2_Rh110 in buffer'!D5)/2 -> 5.995364 | E7: =$D$2+1/$D$3*($D$8/(1+A7/$D$4)/SQRT(1+A7/$D$4/$D$5/$D$5)+(1-$D$8)/(1+A7/$D$6)/SQRT(1+A7/$D$6/$D$7/$D$7))*(1+$D$9*EXP(-A7/$D$10)+$D$11*EXP(-A7/$D$12)) -> 1.2991563 | F7: =B7-E7 -> 0.001603712
A8: 2.8e-05 | B8: 1.30145 | C8: x1 | D8: 1 | E8: =$D$2+1/$D$3*($D$8/(1+A8/$D$4)/SQRT(1+A8/$D$4/$D$5/$D$5)+(1-$D$8)/(1+A8/$D$6)/SQRT(1+A8/$D$6/$D$7/$D$7))*(1+$D$9*EXP(-A8/$D$10)+$D$11*EXP(-A8/$D$12)) -> 1.2988918 | F8: =B8-E8 -> 0.0025582126
A9: 3.2e-05 | B9: 1.29396 | C9: KT | D9: 0.1399568 | E9: =$D$2+1/$D$3*($D$8/(1+A9/$D$4)/SQRT(1+A9/$D$4/$D$5/$D$5)+(1-$D$8)/(1+A9/$D$6)/SQRT(1+A9/$D$6/$D$7/$D$7))*(1+$D$9*EXP(-A9/$D$10)+$D$11*EXP(-A9/$D$12)) -> 1.2986299 | F9: =B9-E9 -> -0.004669871
A10: 3.6e-05 | B10: 1.30024 | C10: tT [ms] | D10: 0.060775192 | E10: =$D$2+1/$D$3*($D$8/(1+A10/$D$4)/SQRT(1+A10/$D$4/$D$5/$D$5)+(1-$D$8)/(1+A10/$D$6)/SQRT(1+A10/$D$6/$D$7/$D$7))*(1+$D$9*EXP(-A10/$D$10)+$D$11*EXP(-A10/$D$12)) -> 1.2983705 | F10: =B10-E10 -> 0.0018694867
A11: 4e-05 | B11: 1.30213 | C11: KR | D11: 0.11862422 | E11: =$D$2+1/$D$3*($D$8/(1+A11/$D$4)/SQRT(1+A11/$D$4/$D$5/$D$5)+(1-$D$8)/(1+A11/$D$6)/SQRT(1+A11/$D$6/$D$7/$D$7))*(1+$D$9*EXP(-A11/$D$10)+$D$11*EXP(-A11/$D$12)) -> 1.2981137 | F11: =B11-E11 -> 0.0040163109
A12: 4.4e-05 | B12: 1.30184 | C12: tR [ms] | D12: 0.00040297976 | E12: =$D$2+1/$D$3*($D$8/(1+A12/$D$4)/SQRT(1+A12/$D$4/$D$5/$D$5)+(1-$D$8)/(1+A12/$D$6)/SQRT(1+A12/$D$6/$D$7/$D$7))*(1+$D$9*EXP(-A12/$D$10)+$D$11*EXP(-A12/$D$12)) -> 1.2978594 | F12: =B12-E12 -> 0.0039806268
A13: 4.8e-05 | B13: 1.29404 | E13: =$D$2+1/$D$3*($D$8/(1+A13/$D$4)/SQRT(1+A13/$D$4/$D$5/$D$5)+(1-$D$8)/(1+A13/$D$6)/SQRT(1+A13/$D$6/$D$7/$D$7))*(1+$D$9*EXP(-A13/$D$10)+$D$11*EXP(-A13/$D$12)) -> 1.2976075 | F13: =B13-E13 -> -0.0035675409
A14: 5.2e-05 | B14: 1.29236 | E14: =$D$2+1/$D$3*($D$8/(1+A14/$D$4)/SQRT(1+A14/$D$4/$D$5/$D$5)+(1-$D$8)/(1+A14/$D$6)/SQRT(1+A14/$D$6/$D$7/$D$7))*(1+$D$9*EXP(-A14/$D$10)+$D$11*EXP(-A14/$D$12)) -> 1.2973582 | F14: =B14-E14 -> -0.0049981677
A15: 5.6e-05 | B15: 1.29857 | E15: =$D$2+1/$D$3*($D$8/(1+A15/$D$4)/SQRT(1+A15/$D$4/$D$5/$D$5)+(1-$D$8)/(1+A15/$D$6)/SQRT(1+A15/$D$6/$D$7/$D$7))*(1+$D$9*EXP(-A15/$D$10)+$D$11*EXP(-A15/$D$12)) -> 1.2971112 | F15: =B15-E15 -> 0.0014587707
A16: 6e-05 | B16: 1.29081 | E16: =$D$2+1/$D$3*($D$8/(1+A16/$D$4)/SQRT(1+A16/$D$4/$D$5/$D$5)+(1-$D$8)/(1+A16/$D$6)/SQRT(1+A16/$D$6/$D$7/$D$7))*(1+$D$9*EXP(-A16/$D$10)+$D$11*EXP(-A16/$D$12)) -> 1.2968667 | F16: =B16-E16 -> -0.0060567016
A17: 6.4e-05 | B17: 1.28985 | E17: =$D$2+1/$D$3*($D$8/(1+A17/$D$4)/SQRT(1+A17/$D$4/$D$5/$D$5)+(1-$D$8)/(1+A17/$D$6)/SQRT(1+A17/$D$6/$D$7/$D$7))*(1+$D$9*EXP(-A17/$D$10)+$D$11*EXP(-A17/$D$12)) -> 1.2966246 | F17: =B17-E17 -> -0.0067745608
A18: 7.2e-05 | B18: 1.3057 | E18: =$D$2+1/$D$3*($D$8/(1+A18/$D$4)/SQRT(1+A18/$D$4/$D$5/$D$5)+(1-$D$8)/(1+A18/$D$6)/SQRT(1+A18/$D$6/$D$7/$D$7))*(1+$D$9*EXP(-A18/$D$10)+$D$11*EXP(-A18/$D$12)) -> 1.2961473 | F18: =B18-E18 -> 0.0095526541
A19: 8e-05 | B19: 1.28215 | E19: =$D$2+1/$D$3*($D$8/(1+A19/$D$4)/SQRT(1+A19/$D$4/$D$5/$D$5)+(1-$D$8)/(1+A19/$D$6)/SQRT(1+A19/$D$6/$D$7/$D$7))*(1+$D$9*EXP(-A19/$D$10)+$D$11*EXP(-A19/$D$12)) -> 1.2956794 | F19: =B19-E19 -> -0.013529399
A20: 8.8e-05 | B20: 1.28869 | E20: =$D$2+1/$D$3*($D$8/(1+A20/$D$4)/SQRT(1+A20/$D$4/$D$5/$D$5)+(1-$D$8)/(1+A20/$D$6)/SQRT(1+A20/$D$6/$D$7/$D$7))*(1+$D$9*EXP(-A20/$D$10)+$D$11*EXP(-A20/$D$12)) -> 1.2952205 | F20: =B20-E20 -> -0.0065305369
A21: 9.6e-05 | B21: 1.29047 | E21: =$D$2+1/$D$3*($D$8/(1+A21/$D$4)/SQRT(1+A21/$D$4/$D$5/$D$5)+(1-$D$8)/(1+A21/$D$6)/SQRT(1+A21/$D$6/$D$7/$D$7))*(1+$D$9*EXP(-A21/$D$10)+$D$11*EXP(-A21/$D$12)) -> 1.2947706 | F21: =B21-E21 -> -0.004300582
A22: 0.000104 | B22: 1.29452 | E22: =$D$2+1/$D$3*($D$8/(1+A22/$D$4)/SQRT(1+A22/$D$4/$D$5/$D$5)+(1-$D$8)/(1+A22/$D$6)/SQRT(1+A22/$D$6/$D$7/$D$7))*(1+$D$9*EXP(-A22/$D$10)+$D$11*EXP(-A22/$D$12)) -> 1.2943294 | F22: =B22-E22 -> 0.00019064111
A23: 0.000112 | B23: 1.28582 | E23: =$D$2+1/$D$3*($D$8/(1+A23/$D$4)/SQRT(1+A23/$D$4/$D$5/$D$5)+(1-$D$8)/(1+A23/$D$6)/SQRT(1+A23/$D$6/$D$7/$D$7))*(1+$D$9*EXP(-A23/$D$10)+$D$11*EXP(-A23/$D$12)) -> 1.2938967 | F23: =B23-E23 -> -0.0080766958
A24: 0.00012 | B24: 1.29728 | E24: =$D$2+1/$D$3*($D$8/(1+A24/$D$4)/SQRT(1+A24/$D$4/$D$5/$D$5)+(1-$D$8)/(1+A24/$D$6)/SQRT(1+A24/$D$6/$D$7/$D$7))*(1+$D$9*EXP(-A24/$D$10)+$D$11*EXP(-A24/$D$12)) -> 1.2934724 | F24: =B24-E24 -> 0.0038075755
... A238: 13958.644 | B238: 1.00377 | E238: =$D$2+1/$D$3*($D$8/(1+A238/$D$4)/SQRT(1+A238/$D$4/$D$5/$D$5)+(1-$D$8)/(1+A238/$D$6)/SQRT(1+A238/$D$6/$D$7/$D$7))*(1+$D$9*EXP(-A238/$D$10)+$D$11*EXP(-A238/$D$12)) -> 1.0026815 | F238: =B238-E238 -> 0.0010884612
A239: 15032.386 | B239: 1.00435
A240: 16106.127 | B240: 1.00516
A241: 17179.869 | B241: 1.00485
A242: 19327.353 | B242: 1.00218
A243: 21474.836 | B243: 1.00281
A244: 23622.32 | B244: 1.00404
A245: 25769.804 | B245: 1.00146
A246: 27917.287 | B246: 1.00371

Sheet 2_Alexa-488-IgG
A1: Corr.Time [ms] | B1: antibody2 | C1: Parameters | E1: model f | F1: res | G1: chi2 | J1: Count rate [kHz] | L1: kcpm
A2: 4e-06 | B2: 1.2459 | C2: offset | D2: 1.0057852 | E2: =$D$2+1/$D$3*($D$8/(1+A2/$D$4)/SQRT(1+A2/$D$4/$D$5/$D$5)+(1-$D$8)/(1+A2/$D$6)/SQRT(1+A2/$D$6/$D$7/$D$7))*(1+$D$9*EXP(-A2/$D$10)+$D$11*EXP(-A2/$D$12)) -> 1.3027147 | F2: =B2-E2 -> -0.056814691 | G2: =SUMSQ(F$4:F$190) -> 0.002225186 | I2: Ch.1 | J2: 131.3 | L2: =(J2+J3)/D3 -> 65.04439
A3: 8e-06 | B3: 1.27972 | C3: N | D3: 4.3278137 | E3: =$D$2+1/$D$3*($D$8/(1+A3/$D$4)/SQRT(1+A3/$D$4/$D$5/$D$5)+(1-$D$8)/(1+A3/$D$6)/SQRT(1+A3/$D$6/$D$7/$D$7))*(1+$D$9*EXP(-A3/$D$10)+$D$11*EXP(-A3/$D$12)) -> 1.2977135 | F3: =B3-E3 -> -0.017993513 | I3: Ch.2 | J3: 150.2
A4: 1.2e-05 | B4: 1.29642 | C4: tD1 [ms] | D4: 1.3813088 | E4: =$D$2+1/$D$3*($D$8/(1+A4/$D$4)/SQRT(1+A4/$D$4/$D$5/$D$5)+(1-$D$8)/(1+A4/$D$6)/SQRT(1+A4/$D$6/$D$7/$D$7))*(1+$D$9*EXP(-A4/$D$10)+$D$11*EXP(-A4/$D$12)) -> 1.2933538 | F4: =B4-E4 -> 0.0030661926
A5: 1.6e-05 | B5: 1.2784 | C5: Zo/Wo | D5: =('1_Rh110 in buffer'!D5+'2_Rh110 in buffer'!D5)/2 -> 5.995364 | E5: =$D$2+1/$D$3*($D$8/(1+A5/$D$4)/SQRT(1+A5/$D$4/$D$5/$D$5)+(1-$D$8)/(1+A5/$D$6)/SQRT(1+A5/$D$6/$D$7/$D$7))*(1+$D$9*EXP(-A5/$D$10)+$D$11*EXP(-A5/$D$12)) -> 1.2895531 | F5: =B5-E5 -> -0.011153101
A6: 2e-05 | B6: 1.292 | C6: tD2 [ms] | D6: 1.38 | E6: =$D$2+1/$D$3*($D$8/(1+A6/$D$4)/SQRT(1+A6/$D$4/$D$5/$D$5)+(1-$D$8)/(1+A6/$D$6)/SQRT(1+A6/$D$6/$D$7/$D$7))*(1+$D$9*EXP(-A6/$D$10)+$D$11*EXP(-A6/$D$12)) -> 1.2862395 | F6: =B6-E6 -> 0.0057604765
